Workbook

Sheet 每日必读
A1: 主题 | B1: 悟道
A2: 系统 | B2: 好的系统一定是适合自己的心态, 对你最大限度的抵抗心态波动, 好的心态是系统第一原则
B3: 不要想着一口吃胖, 一年中几次重仓必杀, 平时小机会积小成多, 就会让你的账户产生良性的复利, 这会使你的心态变的更加平稳
B4: 好的系统会让你大盘涨时你涨, 大盘跌时你小跌或不跌, 赚钱会变的很自然, 这都会让你更加自信
B5: 好的仓位控制会让你在回撤时也不让你难受, 这是一个很不错的心态控制方式(敢于低位空仓, 敢于高位满仓)
B6: 止损 - 不存在的, 果断卖出不确定就是最好的止损, 止损要简单, 越简单越好, 盈利全交给概率. 克服心理障碍是稳定止损的先决条件, 不要因为被套几个点就犹豫不决.
B7: 好的系统绝对会反应在你的账户上, 当你的账户出现良性曲线时一定要对自己进行总结
A8: 情绪 | B8: 时刻思考场内和场外的想法, 而不是抱怨, 要做情绪的追踪者
B9: 高手要借助市场的贪婪和恐慌反过来指导决策, 着眼点在整个市场
B10: 连板的增多就会出现追龙头效应
B11: 抄底反包的增多会出现追抄底效应
B12: 追热点如果出现赚钱效应, 那么就会出现追热点狂潮
A13: 主板 | B13: 主板 = 持续热度 + 持续赚钱效应
B14: 主板龙头是大盘风向标, 一定要时刻盯住
B15: 主板龙头到顶时, 板块热度尚在, 那么就会出现补涨龙
B16: 追板要看市场环境, 热点, 成交量, 价格, 当然最重要的是场内和场外人的心理变化
A17: 周期 | B17: 强势阶段 - 一定要选择最强(买龙头只是手段, 卖龙头才是高手)
B18: 初期(低吸止损) - 选择做强势股的回调反抽, 或者新热点. 强股形态尚未完全破坏, 市场仍有期待会有新高, 因此可以做回调的反抽
B19: 中期(低吸崩溃) - 选择做超跌股, 重点在时机, 一般是连续下跌一段后的再度猛跌时, 有部分买盘会推动超跌股进行一定的反弹, 也可以耐心等待不做任何动作
B20: 末期(追涨强势) - 符合主流热点有爆发力的强势股
B21: 阶段的判断本身就是一个动态的过程, 可能会有预判错误, 但是需要一定的策略来弥补过错
A22: 选股 | B22: 买股前, 一定要问自己假如你是空仓, 你会买它吗, 也许这时答案就会在眼前
B23: 买股一定要问自己能不能看到30%, 如果跌时敢不敢追. 选股一定要机会大于风险
B24: 大盘不好, 个股没有热点那么就不要买, 要买就买确定性
B25: 一个股的上涨一定要理解上涨原因, 若无法理解最好就不要碰
B26: 尾盘买股需要对第二天的预期热点持续性有判断
B27: 之后会有持续性的热点领导市场上涨, 选择符合主流热点又爆发力的强势股, 也许后市还有低点, 但是随着盘面的出现把筹码放到最有爆发力的个股上是很好的策略

Sheet 收益表
A1: 月份 | B1: 增量资金 | C1: 倍数1.1 | D1: 金额 | E1: 倍数1.15 | F1: 金额 | G1: 倍数1.2 | H1: 金额 | I1: 倍数1.25 | J1: 金额 | K1: 倍数1.3 | L1: 金额 | M1: 倍数1.35 | N1: 金额 | O1: 倍数1.4 | P1: 金额 | Q1: 倍数1.45 | R1: 金额
A2: 45658 | B2: 0 | C2: 1 | D2: 30000 | E2: 1 | F2: 30000 | G2: 1 | H2: 30000 | I2: 1 | J2: 30000 | K2: 1 | L2: 30000 | M2: 1 | N2: 30000 | O2: 1 | P2: 30000 | Q2: 1 | R2: 30000
A3: 45689 | B3: 0 | C3: 1.1 | D3: =$C$3*(D2+B3) -> 33000 | E3: 1.15 | F3: =$E$3*(F2+B3) -> 34500 | G3: 1.2 | H3: =$G$3*(H2+B3) -> 36000 | I3: 1.25 | J3: =$I$3*(J2+B3) -> 37500 | K3: 1.3 | L3: =$K$3*(L2+B3) -> 39000 | M3: 1.35 | N3: =$M$3*(N2+B3) -> 40500 | O3: 1.4 | P3: =$O$3*(P2+B3) -> 42000 | Q3: 1.45 | R3: =$Q$3*(R2+B3) -> 43500
A4: 45717 | B4: 0 | C4: =POWER($C$3,B88) -> 1.21 | D4: =$C$3*(D3+B4) -> 36300 | E4: =POWER($E$3,B88) -> 1.3225 | F4: =$E$3*(F3+B4) -> 39675 | G4: =POWER($G$3,B88) -> 1.44 | H4: =$G$3*(H3+B4) -> 43200 | I4: =POWER($I$3,B88) -> 1.5625 | J4: =$I$3*(J3+B4) -> 46875 | K4: =POWER($K$3,B88) -> 1.69 | L4: =$K$3*(L3+B4) -> 50700 | M4: =POWER($M$3,B88) -> 1.8225 | N4: =$M$3*(N3+B4) -> 54675 | O4: =POWER($O$3,B88) -> 1.96 | P4: =$O$3*(P3+B4) -> 58800 | Q4: =POWER($Q$3,B88) -> 2.1025 | R4: =$Q$3*(R3+B4) -> 63075
A5: 45748 | B5: 0 | C5: =POWER($C$3,B89) -> 1.331 | D5: =$C$3*(D4+B5) -> 39930 | E5: =POWER($E$3,B89) -> 1.520875 | F5: =$E$3*(F4+B5) -> 45626.25 | G5: =POWER($G$3,B89) -> 1.728 | H5: =$G$3*(H4+B5) -> 51840 | I5: =POWER($I$3,B89) -> 1.953125 | J5: =$I$3*(J4+B5) -> 58593.75 | K5: =POWER($K$3,B89) -> 2.197 | L5: =$K$3*(L4+B5) -> 65910 | M5: =POWER($M$3,B89) -> 2.460375 | N5: =$M$3*(N4+B5) -> 73811.25 | O5: =POWER($O$3,B89) -> 2.744 | P5: =$O$3*(P4+B5) -> 82320 | Q5: =POWER($Q$3,B89) -> 3.048625 | R5: =$Q$3*(R4+B5) -> 91458.75
A6: 45778 | B6: 0 | C6: =POWER($C$3,B90) -> 1.4641 | D6: =$C$3*(D5+B6) -> 43923 | E6: =POWER($E$3,B90) -> 1.7490063 | F6: =$E$3*(F5+B6) -> 52470.188 | G6: =POWER($G$3,B90) -> 2.0736 | H6: =$G$3*(H5+B6) -> 62208 | I6: =POWER($I$3,B90) -> 2.4414062 | J6: =$I$3*(J5+B6) -> 73242.188 | K6: =POWER($K$3,B90) -> 2.8561 | L6: =$K$3*(L5+B6) -> 85683 | M6: =POWER($M$3,B90) -> 3.3215063 | N6: =$M$3*(N5+B6) -> 99645.188 | O6: =POWER($O$3,B90) -> 3.8416 | P6: =$O$3*(P5+B6) -> 115248 | Q6: =POWER($Q$3,B90) -> 4.4205062 | R6: =$Q$3*(R5+B6) -> 132615.19
A7: 45809 | B7: 0 | C7: =POWER($C$3,B91) -> 1.61051 | D7: =$C$3*(D6+B7) -> 48315.3 | E7: =POWER($E$3,B91) -> 2.0113572 | F7: =$E$3*(F6+B7) -> 60340.716 | G7: =POWER($G$3,B91) -> 2.48832 | H7: =$G$3*(H6+B7) -> 74649.6 | I7: =POWER($I$3,B91) -> 3.0517578 | J7: =$I$3*(J6+B7) -> 91552.734 | K7: =POWER($K$3,B91) -> 3.71293 | L7: =$K$3*(L6+B7) -> 111387.9 | M7: =POWER($M$3,B91) -> 4.4840334 | N7: =$M$3*(N6+B7) -> 134521 | O7: =POWER($O$3,B91) -> 5.37824 | P7: =$O$3*(P6+B7) -> 161347.2 | Q7: =POWER($Q$3,B91) -> 6.4097341 | R7: =$Q$3*(R6+B7) -> 192292.02
A8: 45839 | B8: 0 | C8: =POWER($C$3,B92) -> 1.771561 | D8: =$C$3*(D7+B8) -> 53146.83 | E8: =POWER($E$3,B92) -> 2.3130608 | F8: =$E$3*(F7+B8) -> 69391.823 | G8: =POWER($G$3,B92) -> 2.985984 | H8: =$G$3*(H7+B8) -> 89579.52 | I8: =POWER($I$3,B92) -> 3.8146973 | J8: =$I$3*(J7+B8) -> 114440.92 | K8: =POWER($K$3,B92) -> 4.826809 | L8: =$K$3*(L7+B8) -> 144804.27 | M8: =POWER($M$3,B92) -> 6.0534451 | N8: =$M$3*(N7+B8) -> 181603.35 | O8: =POWER($O$3,B92) -> 7.529536 | P8: =$O$3*(P7+B8) -> 225886.08 | Q8: =POWER($Q$3,B92) -> 9.2941144 | R8: =$Q$3*(R7+B8) -> 278823.43
A9: 45870 | B9: 0 | C9: =POWER($C$3,B93) -> 1.9487171 | D9: =$C$3*(D8+B9) -> 58461.513 | E9: =POWER($E$3,B93) -> 2.6600199 | F9: =$E$3*(F8+B9) -> 79800.596 | G9: =POWER($G$3,B93) -> 3.5831808 | H9: =$G$3*(H8+B9) -> 107495.42 | I9: =POWER($I$3,B93) -> 4.7683716 | J9: =$I$3*(J8+B9) -> 143051.15 | K9: =POWER($K$3,B93) -> 6.2748517 | L9: =$K$3*(L8+B9) -> 188245.55 | M9: =POWER($M$3,B93) -> 8.1721509 | N9: =$M$3*(N8+B9) -> 245164.53 | O9: =POWER($O$3,B93) -> 10.54135 | P9: =$O$3*(P8+B9) -> 316240.51 | Q9: =POWER($Q$3,B93) -> 13.476466 | R9: =$Q$3*(R8+B9) -> 404293.98
A10: 45901 | B10: 0 | C10: =POWER($C$3,B94) -> 2.1435888 | D10: =$C$3*(D9+B10) -> 64307.664 | E10: =POWER($E$3,B94) -> 3.0590229 | F10: =$E$3*(F9+B10) -> 91770.686 | G10: =POWER($G$3,B94) -> 4.299817 | H10: =$G$3*(H9+B10) -> 128994.51 | I10: =POWER($I$3,B94) -> 5.9604645 | J10: =$I$3*(J9+B10) -> 178813.93 | K10: =POWER($K$3,B94) -> 8.1573072 | L10: =$K$3*(L9+B10) -> 244719.22 | M10: =POWER($M$3,B94) -> 11.032404 | N10: =$M$3*(N9+B10) -> 330972.11 | O10: =POWER($O$3,B94) -> 14.757891 | P10: =$O$3*(P9+B10) -> 442736.72 | Q10: =POWER($Q$3,B94) -> 19.540876 | R10: =$Q$3*(R9+B10) -> 586226.27
A11: 45931 | B11: 0 | C11: =POWER($C$3,B95) -> 2.3579477 | D11: =$C$3*(D10+B11) -> 70738.431 | E11: =POWER($E$3,B95) -> 3.5178763 | F11: =$E$3*(F10+B11) -> 105536.29 | G11: =POWER($G$3,B95) -> 5.1597804 | H11: =$G$3*(H10+B11) -> 154793.41 | I11: =POWER($I$3,B95) -> 7.4505806 | J11: =$I$3*(J10+B11) -> 223517.42 | K11: =POWER($K$3,B95) -> 10.604499 | L11: =$K$3*(L10+B11) -> 318134.98 | M11: =POWER($M$3,B95) -> 14.893745 | N11: =$M$3*(N10+B11) -> 446812.35 | O11: =POWER($O$3,B95) -> 20.661047 | P11: =$O$3*(P10+B11) -> 619831.4 | Q11: =POWER($Q$3,B95) -> 28.334269 | R11: =$Q$3*(R10+B11) -> 850028.08
A12: 45962 | B12: 0 | C12: =POWER($C$3,B96) -> 2.5937425 | D12: =$C$3*(D11+B12) -> 77812.274 | E12: =POWER($E$3,B96) -> 4.0455577 | F12: =$E$3*(F11+B12) -> 121366.73 | G12: =POWER($G$3,B96) -> 6.1917364 | H12: =$G$3*(H11+B12) -> 185752.09 | I12: =POWER($I$3,B96) -> 9.3132257 | J12: =$I$3*(J11+B12) -> 279396.77 | K12: =POWER($K$3,B96) -> 13.785849 | L12: =$K$3*(L11+B12) -> 413575.48 | M12: =POWER($M$3,B96) -> 20.106556 | N12: =$M$3*(N11+B12) -> 603196.68 | O12: =POWER($O$3,B96) -> 28.925465 | P12: =$O$3*(P11+B12) -> 867763.96 | Q12: =POWER($Q$3,B96) -> 41.084691 | R12: =$Q$3*(R11+B12) -> 1232540.7
A13: 45992 | B13: 0 | C13: =POWER($C$3,B97) -> 2.8531167 | D13: =$C$3*(D12+B13) -> 85593.501 | E13: =POWER($E$3,B97) -> 4.6523914 | F13: =$E$3*(F12+B13) -> 139571.74 | G13: =POWER($G$3,B97) -> 7.4300837 | H13: =$G$3*(H12+B13) -> 222902.51 | I13: =POWER($I$3,B97) -> 11.641532 | J13: =$I$3*(J12+B13) -> 349245.97 | K13: =POWER($K$3,B97) -> 17.921604 | L13: =$K$3*(L12+B13) -> 537648.12 | M13: =POWER($M$3,B97) -> 27.14385 | N13: =$M$3*(N12+B13) -> 814315.51 | O13: =POWER($O$3,B97) -> 40.495652 | P13: =$O$3*(P12+B13) -> 1214869.6 | Q13: =POWER($Q$3,B97) -> 59.572802 | R13: =$Q$3*(R12+B13) -> 1787184
A15: 日期 | B15: 天数 | C15: Ratio(3.0%) | D15: 金额 | E15: Ratio(2.0%) | F15: 金额 | G15: Ratio (1.5%) | H15: 金额 | I15: Ratio(1.0%) | J15: 金额 | K15: 增量资金 | L15: 盘前金额 | M15: 盈利 | N15: 实际涨幅 | O15: 盘后金额 | P15: 目标涨幅(1.0%) | T15: 涨停数 | U15: 跌停数
A16: 45586 | K16: 0 | L16: 24127.35 | M16: 0 | N16: 0 | O16: 24127.35 | T16: 190 | U16: 0
A17: 45587 | K17: 0 | L17: =IF(K17>0,K17+O16,O16) -> 24127.35 | M17: =(O17-L17)/L17 -> 0.079366362 | N17: =O17/($L$16+SUM($K$16:K17))-1 -> 0.079366362 | O17: 26042.25 | T17: 132 | U17: 0
A18: 45588 | K18: 0 | L18: =IF(K18>0,K18+O17,O17) -> 26042.25 | M18: =(O18-L18)/L18 -> 0.0088279623 | N18: =O18/($L$16+SUM($K$16:K18))-1 -> 0.088894968 | O18: 26272.15 | T18: 127 | U18: 2
A19: 45589 | K19: 0 | L19: =IF(K19>0,K19+O18,O18) -> 26272.15 | M19: =(O19-L19)/L19 -> -0.0065617013 | N19: =O19/($L$16+SUM($K$16:K19))-1 -> 0.081749964 | O19: 26099.76 | T19: 133 | U19: 3
A20: 45590 | K20: 0 | L20: =IF(K20>0,K20+O19,O19) -> 26099.76 | M20: =(O20-L20)/L20 -> 0.034094183 | N20: =O20/($L$16+SUM($K$16:K20))-1 -> 0.11863135 | O20: 26989.61 | T20: 191 | U20: 1
A21: 45593 | K21: 6000 | L21: =IF(K21>0,K21+O20,O20) -> 32989.61 | M21: =(O21-L21)/L21 -> 0.027312842 | N21: =O21/($L$16+SUM($K$16:K21))-1 -> 0.12491308 | O21: 33890.65 | T21: 294 | U21: 1
A22: 45594 | K22: 0 | L22: =IF(K22>0,K22+O21,O21) -> 33890.65 | M22: =(O22-L22)/L22 -> 0.030127484 | N22: =O22/($L$16+SUM($K$16:K22))-1 -> 0.15880388 | O22: 34911.69 | T22: 152 | U22: 19
A23: 45595 | K23: 0 | L23: =IF(K23>0,K23+O22,O22) -> 34911.69 | M23: =(O23-L23)/L23 -> 0.092977739 | N23: =O23/($L$16+SUM($K$16:K23))-1 -> 0.26654684 | O23: 38157.7 | T23: 194 | U23: 8
A24: 45596 | K24: 0 | L24: =IF(K24>0,K24+O23,O23) -> 38157.7 | M24: =(O24-L24)/L24 -> 0.060590654 | N24: =O24/($L$16+SUM($K$16:K24))-1 -> 0.34328774 | O24: 40469.7 | T24: 212 | U24: 14
A25: 45597 | K25: 0 | L25: =IF(K25>0,K25+O24,O24) -> 40469.7 | M25: =(O25-L25)/L25 -> -0.073424809 | N25: =O25/($L$16+SUM($K$16:K25))-1 -> 0.2446571 | O25: 37498.22 | T25: 124 | U25: 165
A26: 45600 | K26: 0 | L26: =IF(K26>0,K26+O25,O25) -> 37498.22 | M26: =(O26-L26)/L26 -> 0.024603835 | N26: =O26/($L$16+SUM($K$16:K26))-1 -> 0.27528043 | O26: 38420.82 | T26: 186 | U26: 43
A27: 45601 | K27: 0 | L27: =IF(K27>0,K27+O26,O26) -> 38420.82 | M27: =(O27-L27)/L27 -> 0.0041839294 | N27: =O27/($L$16+SUM($K$16:K27))-1 -> 0.28061612 | O27: 38581.57 | T27: 218 | U27: 2
A28: 45602 | K28: 0 | L28: =IF(K28>0,K28+O27,O27) -> 38581.57 | M28: =(O28-L28)/L28 -> -0.0042636938 | N28: =O28/($L$16+SUM($K$16:K28))-1 -> 0.27515596 | O28: 38417.07 | T28: 181 | U28: 7
... A85: 45684 | K85: 0 | L85: =IF(K85>0,K85+O84,O84) -> 27324.92 | M85: =(O85-L85)/L85 -> 0.095095612 | N85: =O85/($L$16+SUM($K$16:K85))-1 -> -0.0067695964 | O85: 29923.4 | T85: 45 | U85: 48
A86: 45693 | B86: 0 | C86: 1 | D86: 30000 | E86: 1 | F86: 30000 | G86: 1 | H86: 30000 | I86: 1 | J86: 30000 | K86: 0 | L86: =IF(K86>0,K86+O85,O85) -> 29923.4 | M86: =(O86-L86)/L86 -> 0.0016709331 | N86: =O86/($L$16+SUM($K$16:K86))-1 -> -0.0051099748 | O86: 29973.4 | P86: 0 | T86: 83 | U86: 45
A87: 45694 | B87: 1 | C87: 1.03 | D87: =($L$16+SUM($K$16:K87))*C87 -> 31031.171 | E87: 1.02 | F87: =($L$16+SUM($K$16:K87))*E87 -> 30729.897 | G87: 1.015 | H87: =($L$16+SUM($K$16:K87))*G87 -> 30579.26 | I87: 1.01 | J87: =($L$16+SUM($K$16:K87))*I87 -> 30428.624 | K87: 0 | L87: =IF(K87>0,K87+O86,O86) -> 29973.4 | M87: =(O87-L87)/L87 -> 0.041415722 | N87: =O87/($L$16+SUM($K$16:K87))-1 -> 0.036094114 | O87: 31214.77 | P87: =I87-1 -> 0.01 | T87: 101 | U87: 4
A88: 45695 | B88: 2 | C88: =POWER($C$87,B88) -> 1.0609 | D88: =($L$16+SUM($K$16:K88))*C88 -> 31962.106 | E88: =POWER($E$87,B88) -> 1.0404 | F88: =($L$16+SUM($K$16:K88))*E88 -> 31344.495 | G88: =POWER($G$87,B88) -> 1.030225 | H88: =($L$16+SUM($K$16:K88))*G88 -> 31037.949 | I88: =POWER($I$87,B88) -> 1.0201 | J88: =($L$16+SUM($K$16:K88))*I88 -> 30732.91 | K88: 0 | L88: =IF(K88>0,K88+O87,O87) -> 31214.77 | M88: =(O88-L88)/L88 -> 0.031715755 | N88: =O88/($L$16+SUM($K$16:K88))-1 -> 0.068954621 | O88: 32204.77 | P88: =I88-1 -> 0.0201 | T88: 93 | U88: 2
A89: 45698 | B89: 3 | C89: =POWER($C$87,B89) -> 1.092727 | D89: =($L$16+SUM($K$16:K89))*C89 -> 32920.969 | E89: =POWER($E$87,B89) -> 1.061208 | F89: =($L$16+SUM($K$16:K89))*E89 -> 31971.385 | G89: =POWER($G$87,B89) -> 1.0456784 | H89: =($L$16+SUM($K$16:K89))*G89 -> 31503.518 | I89: =POWER($I$87,B89) -> 1.030301 | J89: =($L$16+SUM($K$16:K89))*I89 -> 31040.239 | K89: 0 | L89: =IF(K89>0,K89+O88,O88) -> 32204.77 | M89: =(O89-L89)/L89 -> -0.00015494599 | N89: =O89/($L$16+SUM($K$16:K89))-1 -> 0.068788991 | O89: 32199.78 | P89: =I89-1 -> 0.030301 | T89: 140 | U89: 2
A90: 45699 | B90: 4 | C90: =POWER($C$87,B90) -> 1.1255088 | D90: =($L$16+SUM($K$16:K90))*C90 -> 33908.598 | E90: =POWER($E$87,B90) -> 1.0824322 | F90: =($L$16+SUM($K$16:K90))*E90 -> 32610.813 | G90: =POWER($G$87,B90) -> 1.0613636 | H90: =($L$16+SUM($K$16:K90))*G90 -> 31976.071 | I90: =POWER($I$87,B90) -> 1.040604 | J90: =($L$16+SUM($K$16:K90))*I90 -> 31350.641 | K90: 0 | L90: =IF(K90>0,K90+O89,O89) -> 32199.78 | M90: =(O90-L90)/L90 -> -0.024398924 | N90: =O90/($L$16+SUM($K$16:K90))-1 -> 0.042711689 | O90: 31414.14 | P90: =I90-1 -> 0.04060401 | T90: 84 | U90: 2
A91: 45700 | B91: 5 | C91: =POWER($C$87,B91) -> 1.1592741 | D91: =($L$16+SUM($K$16:K91))*C91 -> 34925.856 | E91: =POWER($E$87,B91) -> 1.1040808 | F91: =($L$16+SUM($K$16:K91))*E91 -> 33263.029 | G91: =POWER($G$87,B91) -> 1.077284 | H91: =($L$16+SUM($K$16:K91))*G91 -> 32455.712 | I91: =POWER($I$87,B91) -> 1.0510101 | J91: =($L$16+SUM($K$16:K91))*I91 -> 31664.148 | K91: 0 | L91: =IF(K91>0,K91+O90,O90) -> 31414.14 | M91: =(O91-L91)/L91 -> 3.1832799e-05 | N91: =O91/($L$16+SUM($K$16:K91))-1 -> 0.042744881 | O91: 31415.14 | P91: =I91-1 -> 0.05101005 | T91: 95 | U91: 2
A92: 45701 | B92: 6 | C92: =POWER($C$87,B92) -> 1.1940523 | D92: =($L$16+SUM($K$16:K92))*C92 -> 35973.631 | E92: =POWER($E$87,B92) -> 1.1261624 | F92: =($L$16+SUM($K$16:K92))*E92 -> 33928.289 | G92: =POWER($G$87,B92) -> 1.0934433 | H92: =($L$16+SUM($K$16:K92))*G92 -> 32942.548 | I92: =POWER($I$87,B92) -> 1.0615202 | J92: =($L$16+SUM($K$16:K92))*I92 -> 31980.789 | K92: 0 | L92: =IF(K92>0,K92+O91,O91) -> 31415.14 | M92: =(O92-L92)/L92 -> -0.00018780753 | N92: =O92/($L$16+SUM($K$16:K92))-1 -> 0.042549046 | O92: 31409.24 | P92: =I92-1 -> 0.061520151 | T92: 74 | U92: 7
A93: 45702 | B93: 7 | C93: =POWER($C$87,B93) -> 1.2298739 | D93: =($L$16+SUM($K$16:K93))*C93 -> 37052.84 | E93: =POWER($E$87,B93) -> 1.1486857 | F93: =($L$16+SUM($K$16:K93))*E93 -> 34606.855 | G93: =POWER($G$87,B93) -> 1.1098449 | H93: =($L$16+SUM($K$16:K93))*G93 -> 33436.686 | I93: =POWER($I$87,B93) -> 1.0721354 | J93: =($L$16+SUM($K$16:K93))*I93 -> 32300.597 | K93: 0 | L93: =IF(K93>0,K93+O92,O92) -> 31409.24 | M93: =(O93-L93)/L93 -> 0.00543598 | N93: =O93/($L$16+SUM($K$16:K93))-1 -> 0.048216322 | O93: 31579.98 | P93: =I93-1 -> 0.072135352 | T93: 87 | U93: 9
A94: 45705 | B94: 8 | C94: =POWER($C$87,B94) -> 1.2667701 | D94: =($L$16+SUM($K$16:K94))*C94 -> 38164.426 | E94: =POWER($E$87,B94) -> 1.1716594 | F94: =($L$16+SUM($K$16:K94))*E94 -> 35298.992 | G94: =POWER($G$87,B94) -> 1.1264926 | H94: =($L$16+SUM($K$16:K94))*G94 -> 33938.236 | I94: =POWER($I$87,B94) -> 1.0828567 | J94: =($L$16+SUM($K$16:K94))*I94 -> 32623.603 | K94: 0 | L94: =IF(K94>0,K94+O93,O93) -> 31579.98 | M94: =(O94-L94)/L94 -> -0.13367963 | N94: =O94/($L$16+SUM($K$16:K94))-1 -> -0.091908847 | O94: 27358.38 | P94: =I94-1 -> 0.082856706 | T94: 114 | U94: 7
A95: 45706 | B95: 9 | C95: =POWER($C$87,B95) -> 1.3047732 | D95: =($L$16+SUM($K$16:K95))*C95 -> 39309.358 | E95: =POWER($E$87,B95) -> 1.1950926 | F95: =($L$16+SUM($K$16:K95))*E95 -> 36004.972 | G95: =POWER($G$87,B95) -> 1.14339 | H95: =($L$16+SUM($K$16:K95))*G95 -> 34447.31 | I95: =POWER($I$87,B95) -> 1.0936853 | J95: =($L$16+SUM($K$16:K95))*I95 -> 32949.839 | K95: 0 | L95: =IF(K95>0,K95+O94,O94) -> 27358.38 | M95: =(O95-L95)/L95 -> 0.022223538 | N95: =O95/($L$16+SUM($K$16:K95))-1 -> -0.071727849 | O95: 27966.38 | P95: =I95-1 -> 0.093685273 | T95: 53 | U95: 21
A96: 45707 | B96: 10 | C96: =POWER($C$87,B96) -> 1.3439164 | D96: =($L$16+SUM($K$16:K96))*C96 -> 40488.639 | E96: =POWER($E$87,B96) -> 1.2189944 | F96: =($L$16+SUM($K$16:K96))*E96 -> 36725.072 | G96: =POWER($G$87,B96) -> 1.1605408 | H96: =($L$16+SUM($K$16:K96))*G96 -> 34964.02 | I96: =POWER($I$87,B96) -> 1.1046221 | J96: =($L$16+SUM($K$16:K96))*I96 -> 33279.337 | K96: 0 | L96: =IF(K96>0,K96+O95,O95) -> 27966.38 | M96: =(O96-L96)/L96 -> -0.013727197 | N96: =O96/($L$16+SUM($K$16:K96))-1 -> -0.084470423 | O96: 27582.48 | P96: =I96-1 -> 0.10462213 | T96: 120 | U96: 4
A97: 45708 | B97: 11 | C97: =POWER($C$87,B97) -> 1.3842339 | D97: =($L$16+SUM($K$16:K97))*C97 -> 41703.298 | E97: =POWER($E$87,B97) -> 1.2433743 | F97: =($L$16+SUM($K$16:K97))*E97 -> 37459.573 | G97: =POWER($G$87,B97) -> 1.1779489 | H97: =($L$16+SUM($K$16:K97))*G97 -> 35488.48 | I97: =POWER($I$87,B97) -> 1.1156683 | J97: =($L$16+SUM($K$16:K97))*I97 -> 33612.131 | K97: 0 | L97: =IF(K97>0,K97+O96,O96) -> 27582.48 | M97: =(O97-L97)/L97 -> 0.017848286 | N97: =O97/($L$16+SUM($K$16:K97))-1 -> -0.068129789 | O97: 28074.78 | P97: =I97-1 -> 0.11566835 | T97: 107 | U97: 1
...

Sheet Coin
B1: DATE | C1: DOLLAR | D1: RATIO | E1: TARGET DOLLAR
A2: 0 | B2: 45885 | C2: 16.65 | D2: 0 | E2: 16.65
A3: 1 | B3: 45886 | C3: 16.81 | D3: =C3/C2-1 -> 0.0096096096 | E3: =E2*1.015 -> 16.89975
A4: 2 | B4: 45887 | C4: 16.72 | D4: =C4/C3-1 -> -0.005353956 | E4: =E3*1.015 -> 17.153246
A5: 3 | B5: 45888 | C5: 16.63 | D5: =C5/C4-1 -> -0.0053827751 | E5: =E4*1.015 -> 17.410545
A6: 4 | B6: 45889 | C6: 17.19 | D6: =C6/C5-1 -> 0.033674083 | E6: =E5*1.015 -> 17.671703
A7: 5 | B7: 45890 | C7: 17.35 | D7: =C7/C6-1 -> 0.0093077371 | E7: =E6*1.015 -> 17.936779
A8: 6 | B8: 45891 | C8: 17.69 | D8: =C8/C7-1 -> 0.019596542 | E8: =E7*1.015 -> 18.20583
A9: 7 | B9: 45892 | C9: 18.06 | D9: =C9/C8-1 -> 0.020915772 | E9: =E8*1.015 -> 18.478918
A10: 8 | B10: 45893 | C10: 18.17 | D10: =C10/C9-1 -> 0.0060908084 | E10: =E9*1.015 -> 18.756102
A11: 9 | B11: 45894 | C11: 18.79 | D11: =C11/C10-1 -> 0.034122179 | E11: =E10*1.015 -> 19.037443
A12: 10 | B12: 45895 | C12: 19.21 | D12: =C12/C11-1 -> 0.022352315 | E12: =E11*1.015 -> 19.323005
A13: 11 | B13: 45896 | C13: 19.09 | D13: =C13/C12-1 -> -0.0062467465 | E13: =E12*1.015 -> 19.61285
A14: 12 | B14: 45897 | C14: 19.61 | D14: =C14/C13-1 -> 0.027239392 | E14: =E13*1.015 -> 19.907043
... A27: 25 | B27: 45910 | C27: 25.22 | D27: =C27/C26-1 -> -0.034456355 | E27: =E26*1.015 -> 24.15824
A28: 26 | B28: 45911 | E28: =E27*1.015 -> 24.520614
A29: 27 | B29: 45912 | E29: =E28*1.015 -> 24.888423
A30: 28 | B30: 45913 | E30: =E29*1.015 -> 25.261749
A31: 29 | B31: 45914 | E31: =E30*1.015 -> 25.640676
A32: 30 | B32: 45915 | E32: =E31*1.015 -> 26.025286
A33: 31 | B33: 45916 | E33: =E32*1.015 -> 26.415665
A34: 32 | B34: 45917 | E34: =E33*1.015 -> 26.8119
A35: 33 | B35: 45918 | E35: =E34*1.015 -> 27.214078
A36: 34 | B36: 45919 | E36: =E35*1.015 -> 27.62229
A37: 35 | B37: 45920 | E37: =E36*1.015 -> 28.036624
A38: 36 | B38: 45921 | E38: =E37*1.015 -> 28.457173
A39: 37 | B39: 45922 | E39: =E38*1.015 -> 28.884031
... A139: 137 | B139: 46022 | E139: =E138*1.015 -> 128.01534

Sheet 二板补涨缩量战法
B1: 二板补涨战法交谊原则 | L1: 月份 | M1: 交易日 | N1: 盈利 | O1: 亏损 | P1: 涨幅 | Q1: 实际涨幅 | R1: 月份 | S1: 交易日 | T1: 盈利 | U1: 亏损 | V1: 涨幅 | W1: 实际涨幅
R2: 45658 | S2: =T2+U2 -> 3 | T2: 3 | U2: 0 | V2: =W2/Q13-1 -> 0.10504463 | W2: 3.7261
B3: 万变不离其宗，一定要观察情绪波动，是最高点释放后的上涨，还是临近最高点 | R3: 45689 | S3: =T3+U3 -> 6 | T3: 3 | U3: 3 | V3: =W3/W2-1 -> -0.058694077 | W3: 3.5074
B4: D-DAY尾盘炸板 | D4: 不影响第二天的情绪 | R4: 45717 | S4: =T4+U4 -> 4 | T4: 1 | U4: 3 | V4: =W4/W3-1 -> -0.094599989 | W4: 3.1756
B5: 涨跌比超过14% | D5: 下一天是急剧危险的一天，不进 | R5: 45748 | S5: =T5+U5 -> 6 | T5: 2 | U5: 4 | V5: =W5/W4-1 -> 0.31490112 | W5: 4.1756
B6: 涨跌比下降至1/3 | D6: 强势一天，可进 | R6: 45778 | S6: =T6+U6 -> 8 | T6: 3 | U6: 5 | V6: =W6/W5-1 -> 0.23948654 | W6: 5.1756
B7: DAY-1主线 | D7: 行情可以继续延申 | R7: 45809 | S7: =T7+U7 -> 10 | T7: 4 | U7: 6 | V7: =W7/W6-1 -> 0.19321431 | W7: 6.1756
B8: 微快速换手板 | D8: 实在没有买入时可以考虑买入，但是需要当日出售 | R8: 45839 | S8: =T8+U8 -> 0
R9: 45870 | S9: =T9+U9 -> 0
R10: 45901 | S10: =T10+U10 -> 0
L11: 45566 | M11: 5 | N11: 5 | O11: 0 | P11: 0.4655 | Q11: 1.4655 | R11: 45931 | S11: =T11+U11 -> 0
L12: 45597 | M12: 9 | N12: 6 | O12: 3 | P12: =Q12/Q11-1 -> 0.43063801 | Q12: 2.0966 | R12: 45962 | S12: =T12+U12 -> 0
L13: 45627 | M13: =N13+O13 -> 7 | N13: 7 | O13: 0 | P13: =Q13/Q11-1 -> 1.300853 | Q13: 3.3719 | R13: 45992 | S13: =T13+U13 -> 0
L14: TOTAL | M14: =SUM(M2:M13) -> 21 | N14: =SUM(N2:N13) -> 18 | O14: =SUM(O2:O13) -> 3 | P14: =AVERAGE(P11:P13) -> 0.73233032 | Q14: 3.3719 | R14: TOTAL | S14: =SUM(S2:S13) -> 37 | T14: =SUM(T2:T13) -> 16 | U14: =SUM(U2:U13) -> 21 | V14: =AVERAGE(V2:V13) -> 0.11655876 | W14: =W3 -> 3.5074
A16: 日期 | B16: 名称 | C16: TYPE | D16: D-DAY | E16: DAY-1 | F16: DAY-2 | G16: DAY-3 | H16: DAY-4 | J16: 定额交易 | K16: WIN | L16: 模式内交易 | M16: WIN | R16: 涨跌比 | S16: 涨停数 | T16: 跌停数 | U16: 异动原因
A17: 45579 | K17: 1 | M17: 1
A18: 45580 | B18: 国泰君安 | C18: 连扳一字 | D18: 0.0692 | E18: -0.0536
A19: 45581 | B19: 宝塔实业 | C19: 低预期快速换手板 | D19: 0.0457 | E19: 跌停
A20: 45582
A21: 45583
A22: 45586 | R22: =T22/S22 -> 0 | S22: =VLOOKUP(INDIRECT("A"&ROW()),收益表!$A$16:$U$10014,20,0) -> 190 | T22: =VLOOKUP(INDIRECT("A"&ROW()),收益表!$A$16:$U$10014,21,0) -> 0
A23: 45587 | R23: =T23/S23 -> 0 | S23: =VLOOKUP(INDIRECT("A"&ROW()),收益表!$A$16:$U$10014,20,0) -> 132 | T23: =VLOOKUP(INDIRECT("A"&ROW()),收益表!$A$16:$U$10014,21,0) -> 0
A24: 45588 | R24: =T24/S24 -> 0.015748031 | S24: =VLOOKUP(INDIRECT("A"&ROW()),收益表!$A$16:$U$10014,20,0) -> 127 | T24: =VLOOKUP(INDIRECT("A"&ROW()),收益表!$A$16:$U$10014,21,0) -> 2
A25: 45589 | B25: 东易日盛 | C25: T字板 | D25: 0 | E25: 涨停 | F25: 涨停 | G25: 涨停 | H25: -0.0373 | J25: 0.1 | K25: =(1+J25)*K17 -> 1.1 | L25: 0.1 | M25: =(1+L25)*M17 -> 1.1 | R25: =T25/S25 -> 0.022556391 | S25: =VLOOKUP(INDIRECT("A"&ROW()),收益表!$A$16:$U$10014,20,0) -> 133 | T25: =VLOOKUP(INDIRECT("A"&ROW()),收益表!$A$16:$U$10014,21,0) -> 3 | U25: 行情好时尾盘炸板不影响第二日继续改善
A26: 45590 | B26: 亚邦股份 | C26: 连扳一字 | D26: 0.0222 | E26: 0.0024 | J26: 0.1 | K26: =(1+J26)*K25 -> 1.21 | L26: 0.1 | M26: =(1+L26)*M25 -> 1.21 | R26: =T26/S26 -> 0.0052356021 | S26: =VLOOKUP(INDIRECT("A"&ROW()),收益表!$A$16:$U$10014,20,0) -> 191 | T26: =VLOOKUP(INDIRECT("A"&ROW()),收益表!$A$16:$U$10014,21,0) -> 1
B27: 岩石股份 | C27: 快速换手板 | D27: 0.018 | E27: 涨停 | F27: 涨停 | G27: 涨停 | H27: 0.0177
A28: 45593 | R28: =T28/S28 -> 0.0034013605 | S28: =VLOOKUP(INDIRECT("A"&ROW()),收益表!$A$16:$U$10014,20,0) -> 294 | T28: =VLOOKUP(INDIRECT("A"&ROW()),收益表!$A$16:$U$10014,21,0) -> 1
A29: 45594 | B29: 深圳业A | C29: 一字板 | D29: 0.0488 | E29: 7.24%(炸板) | J29: 0.0724 | K29: =(1+J29)*K26 -> 1.297604 | L29: 0.0724 | M29: =(1+L29)*M26 -> 1.297604 | R29: =T29/S29 -> 0.125 | S29: =VLOOKUP(INDIRECT("A"&ROW()),收益表!$A$16:$U$10014,20,0) -> 152 | T29: =VLOOKUP(INDIRECT("A"&ROW()),收益表!$A$16:$U$10014,21,0) -> 19
A30: 45595 | B30: 怡亚通 | C30: 一字板 | D30: 0.0868 | E30: 0.026 | F30: 炸板 | J30: 0.026 | K30: =(1+J30)*K29 -> 1.3313417 | L30: 0.026 | M30: =(1+L30)*M29 -> 1.3313417 | R30: =T30/S30 -> 0.041237113 | S30: =VLOOKUP(INDIRECT("A"&ROW()),收益表!$A$16:$U$10014,20,0) -> 194 | T30: =VLOOKUP(INDIRECT("A"&ROW()),收益表!$A$16:$U$10014,21,0) -> 8
B31: 澳柯玛 | C31: 低预期快速换手板 | D31: 0.0476 | E31: 跌停
A32: 45596 | B32: 中科金财 | C32: 放量快速换手 | D32: -0.04 | E32: 涨停 | F32: -0.0251 | G32: -0.0776 | H32: 0.0284 | J32: 0.1 | K32: =(1+J32)*K30 -> 1.4644759 | L32: 0.1 | M32: =(1+L32)*M30 -> 1.4644759 | R32: =T32/S32 -> 0.066037736 | S32: =VLOOKUP(INDIRECT("A"&ROW()),收益表!$A$16:$U$10014,20,0) -> 212 | T32: =VLOOKUP(INDIRECT("A"&ROW()),收益表!$A$16:$U$10014,21,0) -> 14
A33: 45597 | B33: 汇绿生态 | C33: 一字板 | D33: 0.0026 | E33: -0.0696 | F33: 0.0042 | G33: 0.0239 | H33: -0.011 | J33: -0.0696 | K33: =(1+J33)*K32 -> 1.3625484 | L33: -0.0696 | M33: =(1+L33)*M32 -> 1.3625484
A34: 45600 | B34: 江南高纤 | C34: 一字板 | D34: 0.0094 | E34: -0.0837 | F34: 0.066 | G34: 0.0095 | H34: 0.0519 | J34: 0.0081 | K34: =(1+J34)*K33 -> 1.373585 | R34: =T34/S34 -> 0.2311828 | S34: =VLOOKUP(INDIRECT("A"&ROW()),收益表!$A$16:$U$10014,20,0) -> 186 | T34: =VLOOKUP(INDIRECT("A"&ROW()),收益表!$A$16:$U$10014,21,0) -> 43
B35: 精伦电子 | C35: 一字板 | D35: -0.0637 | E35: 涨停 | F35: 0.0179 | G35: 涨停 | H35: -0.0196
B36: 常山北明 | C36: 低预期快速换手板 | D36: -0.0999 | E36: 涨停
A37: 45601 | B37: 森特股份 | C37: 连扳一字 | D37: 0.0258 | E37: 涨停 | R37: =T37/S37 -> 0.0091743119 | S37: =VLOOKUP(INDIRECT("A"&ROW()),收益表!$A$16:$U$10014,20,0) -> 218 | T37: =VLOOKUP(INDIRECT("A"&ROW()),收益表!$A$16:$U$10014,21,0) -> 2
A38: 45602 | B38: 剑桥科技 | C38: 低预期快速换手板 | D38: 0.028 | E38: 0.0011 | R38: =T38/S38 -> 0.038674033 | S38: =VLOOKUP(INDIRECT("A"&ROW()),收益表!$A$16:$U$10014,20,0) -> 181 | T38: =VLOOKUP(INDIRECT("A"&ROW()),收益表!$A$16:$U$10014,21,0) -> 7
A39: 45603 | B39: 五矿资本 | C39: 低预期快速换手板 | D39: -0.0225 | E39: 0.0126 | J39: 0.1 | K39: =(1+J39)*K34 -> 1.5109435 | L39: 0.1 | M39: =(1+L39)*M33 -> 1.4988032 | R39: =T39/S39 -> 0.042918455 | S39: =VLOOKUP(INDIRECT("A"&ROW()),收益表!$A$16:$U$10014,20,0) -> 233 | T39: =VLOOKUP(INDIRECT("A"&ROW()),收益表!$A$16:$U$10014,21,0) -> 10
B40: 新力金融 | C40: 一字板 | D40: 0.0193 | E40: 涨停 | F40: 跌停 | G40: -0.0328 | H40: -0.0254
A41: 45604 | B41: 中信海直 | C41: 放量T字 | D41: 0.0213 | E41: 7.92%(炸板) | J41: 0.09 | K41: =(1+J41)*K39 -> 1.6469284 | L41: 0.09 | M41: =(1+L41)*M39 -> 1.6336955 | R41: =T41/S41 -> 0.038709677 | S41: =VLOOKUP(INDIRECT("A"&ROW()),收益表!$A$16:$U$10014,20,0) -> 155 | T41: =VLOOKUP(INDIRECT("A"&ROW()),收益表!$A$16:$U$10014,21,0) -> 6
...

Sheet 二板放量+
A1: 日期 | B1: 名称 | C1: D-DAY | D1: DAY-1 | E1: DAY-2 | F1: DAY-3 | G1: 模式内交易 | H1: WIN | L1: 涨跌比 | M1: 涨停数 | N1: 跌停数
A2: 45811
A3: 45812
A4: 45813
A5: 45814
A6: 45817 | B6: 龙蟠科技 | C6: -0.0503 | D6: 0.0378 | E6: 0.0153 | F6: 涨停
A7: 45818
A8: 45819 | B8: 新联电子 | C8: -0.0282 | D8: 0.0838 | E8: -0.0694 | F8: -0.039
B9: 苏利股份
A10: 45820
A11: 45821 | B11: 旭光电子
A12: 45824
A13: 45825 | B13: 宁波韵升
A14: 45826
A15: 45827 | B15: 恒宝股份
A16: 45828
A17: 45831
A18: 45832
A19: 45833
A20: 45834
A21: 45835
A22: 45838 | B22: 湘财股份
A23: 45839 | B23: 建设工业
B24: 南华期货
A25: 45840
A26: 45841
A27: 45842
A28: 45845
A29: 45846
A30: 45847
A31: 45848 | B31: 京北方
B32: 兄弟科技
A33: 45849 | B33: 新亚电子
A34: 45852 | B34: 长春一东
A35: 45853
A36: 45854
A37: 45855 | B37: 中大力德
A38: 45856
A39: 45859 | B39: 奥赛康
A40: 45860
...

Sheet 二板补涨放量战法
E1: 月份 | F1: 交易日 | G1: 盈利 | H1: 亏损 | I1: 涨幅 | J1: 实际涨幅 | K1: 月份 | L1: 交易日 | M1: 盈利 | N1: 亏损 | O1: 涨幅 | P1: 实际涨幅
E2: 45658 | F2: =G2+H2 -> 7 | G2: 7 | H2: 0 | I2: 0.8194 | J2: 1.8194 | K2: 46023
E3: 45689 | F3: 1 | G3: 2 | H3: 0 | I3: =J3/J2-1 -> 0.066175662 | J3: 1.9398 | K3: 46054
E4: 45717 | F4: 1 | G4: 1 | H4: 0 | I4: 0.0389 | J4: 2.9398 | K4: 46082
E5: 45748 | K5: 46113
E6: 45778 | K6: 46143
E7: 45809 | K7: 46174
E8: 45839 | K8: 46204
E9: 45870 | K9: 46235
E10: 45901 | K10: 46266
E11: 45931 | K11: 46296
E12: 45962 | K12: 46327
E13: 45992 | K13: 46357
E14: TOTAL | F14: =SUM(F2:F13) -> 9 | G14: =SUM(G2:G13) -> 10 | H14: =SUM(H2:H13) -> 0 | I14: =AVERAGE(I2:I13) -> 0.30815855 | J14: =J3 -> 1.9398 | K14: TOTAL
A16: 日期 | B16: 名称 | C16: D-DAY | D16: DAY-1 | E16: DAY-2 | F16: 模式内交易 | G16: WIN | K16: 涨跌比 | L16: 涨停数 | M16: 跌停数
A17: 45659 | G17: 1 | K17: =M17/L17 -> 0.47761194 | L17: =VLOOKUP(INDIRECT("A"&ROW()),收益表!$A$16:$U$10014,20,0) -> 67 | M17: =VLOOKUP(INDIRECT("A"&ROW()),收益表!$A$16:$U$10014,21,0) -> 32
A18: 45660 | B18: 宝泰隆 | C18: -0.093 | D18: 涨停 | E18: 0.0433 | F18: 0.1 | G18: =(1+F18)*G17 -> 1.1 | H18: 反弹初期 市场风格是高开低走 | K18: =M18/L18 -> 2.0181818 | L18: =VLOOKUP(INDIRECT("A"&ROW()),收益表!$A$16:$U$10014,20,0) -> 55 | M18: =VLOOKUP(INDIRECT("A"&ROW()),收益表!$A$16:$U$10014,21,0) -> 111
B19: 仁智股份 | C19: 0.0047 | D19: 跌停 | E19: -0.0859 | N19: MA5买入不亏
A20: 45663 | B20: 华资实业 | C20: 跌停 | D20: 涨停 | E20: 0.0438 | F20: 0.1 | G20: =(1+F20)*G18 -> 1.21 | K20: =M20/L20 -> 1.3382353 | L20: =VLOOKUP(INDIRECT("A"&ROW()),收益表!$A$16:$U$10014,20,0) -> 68 | M20: =VLOOKUP(INDIRECT("A"&ROW()),收益表!$A$16:$U$10014,21,0) -> 91
A21: 45664 | B21: 美邦服饰 | C21: -0.0163 | D21: 涨停 | E21: -1.5%(炸板) | F21: 0.1 | G21: =(1+F21)*G20 -> 1.331 | K21: =M21/L21 -> 0.17307692 | L21: =VLOOKUP(INDIRECT("A"&ROW()),收益表!$A$16:$U$10014,20,0) -> 104 | M21: =VLOOKUP(INDIRECT("A"&ROW()),收益表!$A$16:$U$10014,21,0) -> 18
B22: 益民集团 | C22: 0.0314 | D22: 跌停 | E22: 涨停 | N22: 离MA5太远，DAY-1不适合买入
A23: 45665 | B23: 永茂泰 | C23: 0.0291 | D23: 跌停 | E23: -0.0531 | K23: =M23/L23 -> 0.12162162 | L23: =VLOOKUP(INDIRECT("A"&ROW()),收益表!$A$16:$U$10014,20,0) -> 74 | M23: =VLOOKUP(INDIRECT("A"&ROW()),收益表!$A$16:$U$10014,21,0) -> 9 | N23: 离MA5有段距离，D-DAY量太大，不适合买入
B24: 哈药股份 | C24: -0.0677 | D24: 0.0726 | E24: -0.0698 | N24: MA5线时可买入
B25: 氯碱化工 | C25: -0.0184 | D25: -0.0238 | E25: -0.02 | N25: MA5线时可买入
B26: 葫芦娃 | C26: 0.0166 | D26: 0.0225 | E26: -0.0515 | N26: MA5线时可买入
B27: 宝鼎科技 | C27: -0.0383 | D27: -0.0607 | E27: 涨停 | N27: MA5线时可买入
A28: 45666 | B28: 柘中股份 | K28: =M28/L28 -> 0.11340206 | L28: =VLOOKUP(INDIRECT("A"&ROW()),收益表!$A$16:$U$10014,20,0) -> 97 | M28: =VLOOKUP(INDIRECT("A"&ROW()),收益表!$A$16:$U$10014,21,0) -> 11
B29: 动力源 | C29: -0.0222 | D29: -0.0373 | N29: MA5线时可买入
B30: 惠而浦
A31: 45667 | B31: 汇洲智能 | C31: -0.0209 | D31: 0.088 | K31: =M31/L31 -> 1.1818182 | L31: =VLOOKUP(INDIRECT("A"&ROW()),收益表!$A$16:$U$10014,20,0) -> 44 | M31: =VLOOKUP(INDIRECT("A"&ROW()),收益表!$A$16:$U$10014,21,0) -> 52 | N31: 离MA5线时可买入
B32: 东方智造 | C32: -0.019 | D32: 0.0133
B33: 顺钠股份 | C33: -6.1%(炸板) | D33: 跌停 | E33: 跌停 | N33: 炸板不适合买入
B34: 瑞芯微 | C34: 0.0845 | D34: -0.0131 | E34: -0.0473 | N34: 炸板不适合买入
A35: 45670 | B35: 神雾节能 | C35: -0.09 | D35: 涨停 | E35: 0.0566 | F35: 0.1 | G35: =(1+F35)*G21 -> 1.4641 | K35: =M35/L35 -> 0.78846154 | L35: =VLOOKUP(INDIRECT("A"&ROW()),收益表!$A$16:$U$10014,20,0) -> 52 | M35: =VLOOKUP(INDIRECT("A"&ROW()),收益表!$A$16:$U$10014,21,0) -> 41
B36: 远程股份 | C36: -0.0876 | D36: 涨停 | E36: 0.0213
B37: 日海智能 | C37: -0.094 | D37: 涨停 | E37: 0.0318
A38: 45671 | B38: 德力股份 | C38: 跌停 | D38: 0.0377 | E38: 跌停 | F38: 0.027 | G38: =(1+F38)*G35 -> 1.5036307 | K38: =M38/L38 -> 0.01910828 | L38: =VLOOKUP(INDIRECT("A"&ROW()),收益表!$A$16:$U$10014,20,0) -> 157 | M38: =VLOOKUP(INDIRECT("A"&ROW()),收益表!$A$16:$U$10014,21,0) -> 3
B39: 郑中设计 | C39: -0.0918 | D39: 0.0146 | E39: 涨停
A40: 45672 | K40: =M40/L40 -> 0.12345679 | L40: =VLOOKUP(INDIRECT("A"&ROW()),收益表!$A$16:$U$10014,20,0) -> 81 | M40: =VLOOKUP(INDIRECT("A"&ROW()),收益表!$A$16:$U$10014,21,0) -> 10
A41: 45673 | B41: 大连友谊 | C41: 0.0518 | D41: 0.0231 | E41: -0.012 | K41: =M41/L41 -> 0.083333333 | L41: =VLOOKUP(INDIRECT("A"&ROW()),收益表!$A$16:$U$10014,20,0) -> 84 | M41: =VLOOKUP(INDIRECT("A"&ROW()),收益表!$A$16:$U$10014,21,0) -> 7
...
