Workbook

Sheet 猫统计
A1: 姓名 | B1: 生日 | C1: 年龄 | D1: 类型 | E1: 预留 | F1: 房间 | G1: 窝数 | H1: No.1 | I1: 配猫日期 | J1: 生产日期 | K1: 天数 | L1: 死亡 | M1: 生存 | N1: No.2 | O1: 配猫日期 | P1: 生产日期 | Q1: 天数 | R1: 死亡 | S1: 生存 | T1: No.3 | U1: 配猫日期 | V1: 生产日期 | W1: 天数 | X1: 死亡 | Y1: 生存 | Z1: No.4 | AA1: 配猫日期 | AB1: 生产日期 | AC1: 天数 | AD1: 死亡 | AE1: 生存 | AF1: No.5 | AG1: 配猫日期 | AH1: 生产日期 | AI1: 天数 | AJ1: 死亡 | AK1: 生存 | AL1: No.6 | AM1: 配猫日期 | AN1: 生产日期 | AO1: 天数 | AP1: 死亡 | AQ1: 生存 | AR1: No.7 | AS1: 配猫日期 | AT1: 生产日期 | AU1: 天数 | AV1: 死亡 | AW1: 生存 | AX1: No.8 | AY1: 配猫日期 | AZ1: 生产日期 | BA1: 天数 | BB1: 死亡 | BC1: 生存 | BD1: No.9 | BE1: 配猫日期 | BF1: 生产日期 | BG1: 天数 | BH1: 死亡 | BI1: 生存 | BJ1: No.10 | BK1: 配猫日期 | BL1: 生产日期 | BM1: 天数 | BN1: 死亡 | BO1: 生存
A2: YUKI的孩子 | B2: 45344 | C2: =(TODAY()-B2)/30 -> 7.5666667 | D2: 种母 | E2: 种母 | F2: 猫舍1F小卧室
A3: YUKI的孩子 | B3: 45344 | C3: =(TODAY()-B3)/30 -> 7.5666667 | D3: 库存猫 | E3: 种母 | F3: 猫舍1F小卧室
A4: 刘亦菲 | B4: 45132 | C4: =(TODAY()-B4)/30 -> 14.633333 | D4: 种公 | E4: 种公 | F4: 猫舍1F大卧室
A5: 咖啡 | B5: 43739 | C5: =(TODAY()-B5)/30 -> 61.066667 | D5: 种母 | E5: 种母 | F5: 猫舍1F大卧室 | G5: =COUNTIFS(猫统计!I5,"<>")+COUNTIFS(猫统计!O5,"<>")+COUNTIFS(猫统计!U5,"<>")+COUNTIFS(猫统计!AA5,"<>")+COUNTIFS(猫统计!AG5,"<>")+COUNTIFS(猫统计!AM5,"<>")+COUNTIFS(猫统计!AS5,"<>")+COUNTIFS(猫统计!AY5,"<>")+COUNTIFS(猫统计!BE5,"<>")+COUNTIFS(猫统计!BK5,"<>") -> 4 | I5: 44442 | J5: 44506 | K5: =J5-I5 -> 64 | L5: 0 | M5: 3 | O5: 44657 | P5: 44722 | Q5: =P5-O5 -> 65 | R5: 0 | S5: 3 | U5: 44959 | V5: 45023 | W5: =V5-U5 -> 64 | X5: 0 | Y5: 4 | AA5: 45386 | AB5: 45452 | AC5: =AB5-AA5 -> 66 | AD5: 0 | AE5: 4
A6: 小鸡仔 | B6: 45347 | C6: =(TODAY()-B6)/30 -> 7.4666667 | D6: 种公 | E6: 种公 | F6: 猫舍1F小卧室
A7: 咖啡的金渐层 | B7: 45452 | C7: =(TODAY()-B7)/30 -> 3.9666667 | D7: 库存猫 | F7: 猫舍1F大卧室
A8: 咖啡的金渐层 | B8: 45452 | C8: =(TODAY()-B8)/30 -> 3.9666667 | D8: 种母 | E8: 种母 | F8: 猫舍1F大卧室
A9: 咖啡的金渐层 | B9: 45452 | C9: =(TODAY()-B9)/30 -> 3.9666667 | D9: 库存猫 | F9: 猫舍1F大卧室
A10: 土豆 | B10: 44394 | C10: =(TODAY()-B10)/30 -> 39.233333 | D10: 库存猫 | F10: 猫舍1F大卧室
A11: KIMI | B11: 43793 | C11: =(TODAY()-B11)/30 -> 59.266667 | D11: 预售 | F11: 猫舍1F大卧室
A12: 哈哈 | B12: 44435 | C12: =(TODAY()-B12)/30 -> 37.866667 | D12: 种母 | F12: 猫舍1F客厅 | G12: =COUNTIFS(猫统计!I12,"<>")+COUNTIFS(猫统计!O12,"<>")+COUNTIFS(猫统计!U12,"<>")+COUNTIFS(猫统计!AA12,"<>")+COUNTIFS(猫统计!AG12,"<>")+COUNTIFS(猫统计!AM12,"<>")+COUNTIFS(猫统计!AS12,"<>")+COUNTIFS(猫统计!AY12,"<>")+COUNTIFS(猫统计!BE12,"<>")+COUNTIFS(猫统计!BK12,"<>") -> 3 | I12: 45222 | J12: 45290 | K12: =J12-I12 -> 68 | L12: 2 | M12: 0 | O12: 45354 | P12: 45419 | Q12: =P12-O12 -> 65 | R12: 1 | S12: 1 | U12: 45477 | V12: 45548 | W12: =V12-U12 -> 71 | X12: 1 | Y12: 1
A13: 哈哈的蓝金加白矮脚 | B13: 45548 | C13: =(TODAY()-B13)/30 -> 0.76666667 | D13: 奶猫 | F13: 猫舍1F客厅
A14: 小鹿 | B14: 44980 | C14: =(TODAY()-B14)/30 -> 19.7 | D14: 预售 | F14: 猫舍1F客厅 | G14: 1 | I14: 45452 | J14: 45521 | K14: =J14-I14 -> 69 | L14: 0 | M14: 4
A15: 小鹿的尾尖樊色金白 | B15: 45521 | C15: =(TODAY()-B15)/30 -> 1.6666667 | D15: 奶猫 | F15: 猫舍1F客厅
A16: 小鹿的樊色金白 | B16: 45521 | C16: =(TODAY()-B16)/30 -> 1.6666667 | D16: 奶猫 | F16: 猫舍1F客厅
A17: 小鹿的双色金白 | B17: 45521 | C17: =(TODAY()-B17)/30 -> 1.6666667 | D17: 奶猫 | F17: 猫舍1F客厅
A18: 小鹿的翅膀金白 | B18: 45521 | C18: =(TODAY()-B18)/30 -> 1.6666667 | D18: 奶猫 | F18: 猫舍1F客厅
A19: 借配的金 | D19: 库存猫 | F19: 猫舍1F客厅 | G19: 1 | I19: 45363 | J19: 45428 | K19: =J19-I19 -> 65 | L19: 0 | M19: 2 | O19: 45504 | P19: 45571 | R19: 1 | S19: 3
A20: 借配金的金渐层 | B20: 45571 | C20: =(TODAY()-B20)/30 -> 0 | D20: 奶猫 | F20: 猫舍1F客厅
A21: 借配金的金白矮脚 | B21: 45571 | C21: =(TODAY()-B21)/30 -> 0 | D21: 奶猫 | F21: 猫舍1F客厅
A22: 借配金的金白矮脚 | B22: 45571 | C22: =(TODAY()-B22)/30 -> 0 | D22: 奶猫 | F22: 猫舍1F客厅
A23: 紫薯的金白 | B23: 45456 | C23: =(TODAY()-B23)/30 -> 3.8333333 | D23: 库存猫 | F23: 猫舍1F客厅
A24: 紫薯的蓝金白 | B24: 45456 | C24: =(TODAY()-B24)/30 -> 3.8333333 | D24: 种母 | E24: 种母 | F24: 猫舍1F客厅
A25: 借配的短鼻金白 | B25: 45428 | C25: =(TODAY()-B25)/30 -> 4.7666667 | D25: 种母 | E25: 种母 | F25: 猫舍1F客厅
A26: 冉冉 | B26: 45258 | C26: =(TODAY()-B26)/30 -> 10.433333 | D26: 种母 | E26: 种母 | F26: 猫舍1F客厅
A27: 香蕉的金白 | B27: 45304 | C27: =(TODAY()-B27)/30 -> 8.9 | D27: 预售 | F27: 猫舍1F客厅
A28: YUKI | B28: 43793 | C28: =(TODAY()-B28)/30 -> 59.266667 | D28: 种母 | F28: 猫舍1F小卧室 | G28: =COUNTIFS(猫统计!I28,"<>")+COUNTIFS(猫统计!O28,"<>")+COUNTIFS(猫统计!U28,"<>")+COUNTIFS(猫统计!AA28,"<>")+COUNTIFS(猫统计!AG28,"<>")+COUNTIFS(猫统计!AM28,"<>")+COUNTIFS(猫统计!AS28,"<>")+COUNTIFS(猫统计!AY28,"<>")+COUNTIFS(猫统计!BE28,"<>")+COUNTIFS(猫统计!BK28,"<>") -> 7 | I28: 44186 | J28: 44251 | K28: =J28-I28 -> 65 | L28: 0 | M28: 4 | O28: 44318 | P28: 44382 | Q28: =P28-O28 -> 64 | R28: 3 | S28: 1 | U28: 44605 | V28: 44671 | W28: =V28-U28 -> 66 | X28: 0 | Y28: 2 | AA28: 44936 | AB28: 45001 | AC28: =AB28-AA28 -> 65 | AD28: 0 | AE28: 3 | AG28: 45093 | AH28: 45159 | AI28: =AH28-AG28 -> 66 | AJ28: 0 | AK28: 5 | AM28: 45277 | AN28: 45344 | AO28: =AN28-AM28 -> 67 | AP28: 1 | AQ28: 2 | AS28: 45476 | AT28: 45542 | AU28: =AT28-AS28 -> 66 | AV28: 1 | AW28: 3
A29: YUKI的金白矮脚 | B29: 45538 | C29: =(TODAY()-B29)/30 -> 1.1 | D29: 奶猫 | F29: 猫舍1F小卧室
A30: YUKI的金渐层 | B30: 45538 | C30: =(TODAY()-B30)/30 -> 1.1 | D30: 奶猫 | F30: 猫舍1F小卧室
A31: YUKI的金渐层 | B31: 45538 | C31: =(TODAY()-B31)/30 -> 1.1 | D31: 奶猫 | F31: 猫舍1F小卧室
A32: 地瓜的孩子 | D32: 库存猫 | F32: 猫舍1F小卧室
A34: 妞妞 | B34: 43221 | G34: =COUNTIFS(猫统计!I34,"<>")+COUNTIFS(猫统计!O34,"<>")+COUNTIFS(猫统计!U34,"<>")+COUNTIFS(猫统计!AA34,"<>")+COUNTIFS(猫统计!AG34,"<>")+COUNTIFS(猫统计!AM34,"<>")+COUNTIFS(猫统计!AS34,"<>")+COUNTIFS(猫统计!AY34,"<>")+COUNTIFS(猫统计!BE34,"<>")+COUNTIFS(猫统计!BK34,"<>") -> 1 | I34: 43969 | J34: 44034 | K34: =J34-I34 -> 65 | L34: 3 | M34: 1
A35: 馒头 | B35: 44097 | G35: =COUNTIFS(猫统计!I35,"<>")+COUNTIFS(猫统计!O35,"<>")+COUNTIFS(猫统计!U35,"<>")+COUNTIFS(猫统计!AA35,"<>")+COUNTIFS(猫统计!AG35,"<>")+COUNTIFS(猫统计!AM35,"<>")+COUNTIFS(猫统计!AS35,"<>")+COUNTIFS(猫统计!AY35,"<>")+COUNTIFS(猫统计!BE35,"<>")+COUNTIFS(猫统计!BK35,"<>") -> 2 | I35: 44035 | J35: 44097 | K35: =J35-I35 -> 62 | L35: 0 | M35: 3 | O35: 44147 | P35: 44213 | Q35: =P35-O35 -> 66 | R35: 1 | S35: 2
A36: 菲菲 | B36: 43717 | G36: =COUNTIFS(猫统计!I36,"<>")+COUNTIFS(猫统计!O36,"<>")+COUNTIFS(猫统计!U36,"<>")+COUNTIFS(猫统计!AA36,"<>")+COUNTIFS(猫统计!AG36,"<>")+COUNTIFS(猫统计!AM36,"<>")+COUNTIFS(猫统计!AS36,"<>")+COUNTIFS(猫统计!AY36,"<>")+COUNTIFS(猫统计!BE36,"<>")+COUNTIFS(猫统计!BK36,"<>") -> 1 | I36: 44154 | J36: 44220 | K36: =J36-I36 -> 66 | L36: 1 | M36: 4
A37: 琉璃 | B37: 43843 | G37: =COUNTIFS(猫统计!I37,"<>")+COUNTIFS(猫统计!O37,"<>")+COUNTIFS(猫统计!U37,"<>")+COUNTIFS(猫统计!AA37,"<>")+COUNTIFS(猫统计!AG37,"<>")+COUNTIFS(猫统计!AM37,"<>")+COUNTIFS(猫统计!AS37,"<>")+COUNTIFS(猫统计!AY37,"<>")+COUNTIFS(猫统计!BE37,"<>")+COUNTIFS(猫统计!BK37,"<>") -> 1 | I37: 44154 | J37: 44220 | K37: =J37-I37 -> 66 | L37: 0 | M37: 3
A38: 憨憨 | B38: 43954 | G38: =COUNTIFS(猫统计!I38,"<>")+COUNTIFS(猫统计!O38,"<>")+COUNTIFS(猫统计!U38,"<>")+COUNTIFS(猫统计!AA38,"<>")+COUNTIFS(猫统计!AG38,"<>")+COUNTIFS(猫统计!AM38,"<>")+COUNTIFS(猫统计!AS38,"<>")+COUNTIFS(猫统计!AY38,"<>")+COUNTIFS(猫统计!BE38,"<>")+COUNTIFS(猫统计!BK38,"<>") -> 1 | I38: 44217 | J38: 44282 | K38: =J38-I38 -> 65 | L38: 2 | M38: 3
A39: 蜜芽 | G39: =COUNTIFS(猫统计!I39,"<>")+COUNTIFS(猫统计!O39,"<>")+COUNTIFS(猫统计!U39,"<>")+COUNTIFS(猫统计!AA39,"<>")+COUNTIFS(猫统计!AG39,"<>")+COUNTIFS(猫统计!AM39,"<>")+COUNTIFS(猫统计!AS39,"<>")+COUNTIFS(猫统计!AY39,"<>")+COUNTIFS(猫统计!BE39,"<>")+COUNTIFS(猫统计!BK39,"<>") -> 1 | I39: 44243 | J39: 44309 | K39: =J39-I39 -> 66 | L39: 1 | M39: 5
A40: 银点 | B40: 43941 | G40: =COUNTIFS(猫统计!I40,"<>")+COUNTIFS(猫统计!O40,"<>")+COUNTIFS(猫统计!U40,"<>")+COUNTIFS(猫统计!AA40,"<>")+COUNTIFS(猫统计!AG40,"<>")+COUNTIFS(猫统计!AM40,"<>")+COUNTIFS(猫统计!AS40,"<>")+COUNTIFS(猫统计!AY40,"<>")+COUNTIFS(猫统计!BE40,"<>")+COUNTIFS(猫统计!BK40,"<>") -> 1 | I40: 44274 | J40: 44342 | K40: =J40-I40 -> 68 | L40: 1 | M40: 0
A41: 糖糖 | B41: 43875 | G41: =COUNTIFS(猫统计!I41,"<>")+COUNTIFS(猫统计!O41,"<>")+COUNTIFS(猫统计!U41,"<>")+COUNTIFS(猫统计!AA41,"<>")+COUNTIFS(猫统计!AG41,"<>")+COUNTIFS(猫统计!AM41,"<>")+COUNTIFS(猫统计!AS41,"<>")+COUNTIFS(猫统计!AY41,"<>")+COUNTIFS(猫统计!BE41,"<>")+COUNTIFS(猫统计!BK41,"<>") -> 1 | I41: 44233 | J41: 44300 | K41: =J41-I41 -> 67 | L41: 1 | M41: 4
...

Sheet 数量统计
A1: 日期 | B1: 种公数量 | C1: 种母数量 | D1: 预备种公数量 | E1: 预备种母数量 | F1: 奶猫数(3个月以下) | G1: 库存猫数 | H1: 种公数 | I1: 种母数 | J1: 其它猫数 | K1: 猫总数 | M1: 种公数量 | N1: 种母数量 | O1: 预备种公数量 | P1: 预备种母数量 | Q1: 奶猫数量(3个月以下) | R1: 库存猫数量(3个月以上) | S1: 种公数 | T1: 种母数 | U1: 其它猫数 | V1: 猫总数
A2: 44470 | B2: 3 | C2: 15 | D2: 2 | E2: 9 | F2: 57 | G2: 24 | H2: 5 | I2: 24 | J2: 81 | K2: 110 | M2: =COUNTIF(猫统计!D:D,"种公") -> 2 | N2: =COUNTIF(猫统计!D:D,"种母") -> 8 | O2: =COUNTIF(猫统计!D:D,"预备种公") -> 0 | P2: =COUNTIF(猫统计!D:D,"预备种母") -> 0 | Q2: =COUNTIF(猫统计!D:D,"奶猫") -> 11 | R2: =COUNTIF(猫统计!D:D,"库存猫")+COUNTIF(猫统计!D:D,"预售") -> 10 | S2: =M2+O2 -> 2 | T2: =N2+P2 -> 8 | U2: =Q2+R2 -> 21 | V2: =S2+T2+U2 -> 31
A3: 44501 | B3: 2 | C3: 8 | D3: 3 | E3: 8 | F3: 34 | G3: 51 | H3: 5 | I3: 16 | J3: 85 | K3: 106
A4: 44531 | B4: 2 | C4: 8 | D4: 3 | E4: 11 | F4: 28 | G4: 33 | H4: 5 | I4: 19 | J4: 61 | K4: 85
A5: 44562 | B5: 2 | C5: 8 | D5: 3 | E5: 12 | F5: 12 | G5: 46 | H5: 5 | I5: 20 | J5: 58 | K5: 83
A6: 44593 | B6: 3 | C6: 18 | D6: 2 | E6: 4 | F6: 15 | G6: 25 | H6: 5 | I6: 22 | J6: 40 | K6: 67
A7: 44621 | B7: 2 | C7: 19 | D7: 2 | E7: 2 | F7: 19 | G7: 24 | H7: 4 | I7: 21 | J7: 43 | K7: 68
A8: 44652 | B8: 2 | C8: 19 | D8: 2 | E8: 2 | F8: 21 | G8: 27 | H8: 4 | I8: 21 | J8: 48 | K8: 73
A9: 44682 | B9: 2 | C9: 17 | D9: 3 | E9: 3 | F9: 18 | G9: 12 | H9: 5 | I9: 20 | J9: 30 | K9: 55
A10: 44713 | B10: 3 | C10: 18 | D10: 2 | E10: 7 | F10: 31 | G10: 17 | H10: 5 | I10: 25 | J10: 48 | K10: 78
A11: 44743 | B11: 3 | C11: 14 | D11: 2 | E11: 7 | F11: 37 | G11: 12 | H11: 5 | I11: 21 | J11: 49 | K11: 75
A12: 44774 | B12: 3 | C12: 16 | D12: 3 | E12: 6 | F12: 21 | G12: 9 | H12: 6 | I12: 22 | J12: 30 | K12: 58
A13: 44805 | B13: 3 | C13: 15 | D13: 3 | E13: 6 | F13: 28 | G13: 12 | H13: 6 | I13: 21 | J13: 40 | K13: 67
A14: 44835 | B14: 3 | C14: 10 | D14: 3 | E14: 6 | F14: 8 | G14: 20 | H14: 6 | I14: 16 | J14: 28 | K14: 50
... A38: 45566 | B38: 2 | C38: 8 | D38: 0 | E38: 0 | F38: 11 | G38: 10 | H38: 2 | I38: 8 | J38: 21 | K38: 31
A39: 45597
A40: 45627

Sheet 繁育统计
A1: 日期 | B1: 产妇数量 | C1: 出生数 | D1: 死亡数 | E1: 存活数 | F1: 季度存活率 | G1: 季度单窝存活数
A2: 44013 | B2: =COUNTIFS(猫统计!J:J,">="&EOMONTH(A2,-1)+1,猫统计!J:J,"<="&EOMONTH(A2,0))+COUNTIFS(猫统计!P:P,">="&EOMONTH(A2,-1)+1,猫统计!P:P,"<="&EOMONTH(A2,0))+COUNTIFS(猫统计!V:V,">="&EOMONTH(A2,-1)+1,猫统计!V:V,"<="&EOMONTH(A2,0))+COUNTIFS(猫统计!AB:AB,">="&EOMONTH(A2,-1)+1,猫统计!AB:AB,"<="&EOMONTH(A2,0))+COUNTIFS(猫统计!AH:AH,">="&EOMONTH(A2,-1)+1,猫统计!AH:AH,"<="&EOMONTH(A2,0))+COUNTIFS(猫统计!AN:AN,">="&EOMONTH(A2,-1)+1,猫统计!AN:AN,"<="&EOMONTH(A2,0))+COUNTIFS(猫统计!AT:AT,">="&EOMONTH(A2,-1)+1,猫统计!AT:AT,"<="&EOMONTH(A2,0))+COUNTIFS(猫统计!AZ:AZ,">="&EOMONTH(A2,-1)+1,猫统计!AZ:AZ,"<="&EOMONTH(A2,0))+COUNTIFS(猫统计!BF:BF,">="&EOMONTH(A2,-1)+1,猫统计!BF:BF,"<="&EOMONTH(A2,0))+COUNTIFS(猫统计!BL:BL,">="&EOMONTH(A2,-1)+1,猫统计!BL:BL,"<="&EOMONTH(A2,0)) -> 1 | C2: =D2+E2 -> 4 | D2: =SUMIFS(猫统计!L:L,猫统计!J:J,">="&EOMONTH(A2,-1)+1,猫统计!J:J,"<="&EOMONTH(A2,0))+SUMIFS(猫统计!R:R,猫统计!P:P,">="&EOMONTH(A2,-1)+1,猫统计!P:P,"<="&EOMONTH(A2,0))+SUMIFS(猫统计!X:X,猫统计!V:V,">="&EOMONTH(A2,-1)+1,猫统计!V:V,"<="&EOMONTH(A2,0))+SUMIFS(猫统计!AD:AD,猫统计!AB:AB,">="&EOMONTH(A2,-1)+1,猫统计!AB:AB,"<="&EOMONTH(A2,0))+SUMIFS(猫统计!AJ:AJ,猫统计!AH:AH,">="&EOMONTH(A2,-1)+1,猫统计!AH:AH,"<="&EOMONTH(A2,0))+SUMIFS(猫统计!AP:AP,猫统计!AN:AN,">="&EOMONTH(A2,-1)+1,猫统计!AN:AN,"<="&EOMONTH(A2,0))+SUMIFS(猫统计!AV:AV,猫统计!AT:AT,">="&EOMONTH(A2,-1)+1,猫统计!AT:AT,"<="&EOMONTH(A2,0))+SUMIFS(猫统计!BB:BB,猫统计!AZ:AZ,">="&EOMONTH(A2,-1)+1,猫统计!AZ:AZ,"<="&EOMONTH(A2,0))+SUMIFS(猫统计!BH:BH,猫统计!BF:BF,">="&EOMONTH(A2,-1)+1,猫统计!BF:BF,"<="&EOMONTH(A2,0))+SUMIFS(猫统计!BN:BN,猫统计!BL:BL,">="&EOMONTH(A2,-1)+1,猫统计!BL:BL,"<="&EOMONTH(A2,0)) -> 3 | E2: =SUMIFS(猫统计!M:M,猫统计!J:J,">="&EOMONTH(A2,-1)+1,猫统计!J:J,"<="&EOMONTH(A2,0))+SUMIFS(猫统计!S:S,猫统计!P:P,">="&EOMONTH(A2,-1)+1,猫统计!P:P,"<="&EOMONTH(A2,0))+SUMIFS(猫统计!Y:Y,猫统计!V:V,">="&EOMONTH(A2,-1)+1,猫统计!V:V,"<="&EOMONTH(A2,0))+SUMIFS(猫统计!AE:AE,猫统计!AB:AB,">="&EOMONTH(A2,-1)+1,猫统计!AB:AB,"<="&EOMONTH(A2,0))+SUMIFS(猫统计!AK:AK,猫统计!AH:AH,">="&EOMONTH(A2,-1)+1,猫统计!AH:AH,"<="&EOMONTH(A2,0))+SUMIFS(猫统计!AQ:AQ,猫统计!AN:AN,">="&EOMONTH(A2,-1)+1,猫统计!AN:AN,"<="&EOMONTH(A2,0))+SUMIFS(猫统计!AW:AW,猫统计!AT:AT,">="&EOMONTH(A2,-1)+1,猫统计!AT:AT,"<="&EOMONTH(A2,0))+SUMIFS(猫统计!BC:BC,猫统计!AZ:AZ,">="&EOMONTH(A2,-1)+1,猫统计!AZ:AZ,"<="&EOMONTH(A2,0))+SUMIFS(猫统计!BI:BI,猫统计!BF:BF,">="&EOMONTH(A2,-1)+1,猫统计!BF:BF,"<="&EOMONTH(A2,0))+SUMIFS(猫统计!BO:BO,猫统计!BL:BL,">="&EOMONTH(A2,-1)+1,猫统计!BL:BL,"<="&EOMONTH(A2,0)) -> 1
A3: 44044 | B3: =COUNTIFS(猫统计!J:J,">="&EOMONTH(A3,-1)+1,猫统计!J:J,"<="&EOMONTH(A3,0))+COUNTIFS(猫统计!P:P,">="&EOMONTH(A3,-1)+1,猫统计!P:P,"<="&EOMONTH(A3,0))+COUNTIFS(猫统计!V:V,">="&EOMONTH(A3,-1)+1,猫统计!V:V,"<="&EOMONTH(A3,0))+COUNTIFS(猫统计!AB:AB,">="&EOMONTH(A3,-1)+1,猫统计!AB:AB,"<="&EOMONTH(A3,0))+COUNTIFS(猫统计!AH:AH,">="&EOMONTH(A3,-1)+1,猫统计!AH:AH,"<="&EOMONTH(A3,0))+COUNTIFS(猫统计!AN:AN,">="&EOMONTH(A3,-1)+1,猫统计!AN:AN,"<="&EOMONTH(A3,0))+COUNTIFS(猫统计!AT:AT,">="&EOMONTH(A3,-1)+1,猫统计!AT:AT,"<="&EOMONTH(A3,0))+COUNTIFS(猫统计!AZ:AZ,">="&EOMONTH(A3,-1)+1,猫统计!AZ:AZ,"<="&EOMONTH(A3,0))+COUNTIFS(猫统计!BF:BF,">="&EOMONTH(A3,-1)+1,猫统计!BF:BF,"<="&EOMONTH(A3,0))+COUNTIFS(猫统计!BL:BL,">="&EOMONTH(A3,-1)+1,猫统计!BL:BL,"<="&EOMONTH(A3,0)) -> 1 | C3: =D3+E3 -> 1 | D3: =SUMIFS(猫统计!L:L,猫统计!J:J,">="&EOMONTH(A3,-1)+1,猫统计!J:J,"<="&EOMONTH(A3,0))+SUMIFS(猫统计!R:R,猫统计!P:P,">="&EOMONTH(A3,-1)+1,猫统计!P:P,"<="&EOMONTH(A3,0))+SUMIFS(猫统计!X:X,猫统计!V:V,">="&EOMONTH(A3,-1)+1,猫统计!V:V,"<="&EOMONTH(A3,0))+SUMIFS(猫统计!AD:AD,猫统计!AB:AB,">="&EOMONTH(A3,-1)+1,猫统计!AB:AB,"<="&EOMONTH(A3,0))+SUMIFS(猫统计!AJ:AJ,猫统计!AH:AH,">="&EOMONTH(A3,-1)+1,猫统计!AH:AH,"<="&EOMONTH(A3,0))+SUMIFS(猫统计!AP:AP,猫统计!AN:AN,">="&EOMONTH(A3,-1)+1,猫统计!AN:AN,"<="&EOMONTH(A3,0))+SUMIFS(猫统计!AV:AV,猫统计!AT:AT,">="&EOMONTH(A3,-1)+1,猫统计!AT:AT,"<="&EOMONTH(A3,0))+SUMIFS(猫统计!BB:BB,猫统计!AZ:AZ,">="&EOMONTH(A3,-1)+1,猫统计!AZ:AZ,"<="&EOMONTH(A3,0))+SUMIFS(猫统计!BH:BH,猫统计!BF:BF,">="&EOMONTH(A3,-1)+1,猫统计!BF:BF,"<="&EOMONTH(A3,0))+SUMIFS(猫统计!BN:BN,猫统计!BL:BL,">="&EOMONTH(A3,-1)+1,猫统计!BL:BL,"<="&EOMONTH(A3,0)) -> 0 | E3: =SUMIFS(猫统计!M:M,猫统计!J:J,">="&EOMONTH(A3,-1)+1,猫统计!J:J,"<="&EOMONTH(A3,0))+SUMIFS(猫统计!S:S,猫统计!P:P,">="&EOMONTH(A3,-1)+1,猫统计!P:P,"<="&EOMONTH(A3,0))+SUMIFS(猫统计!Y:Y,猫统计!V:V,">="&EOMONTH(A3,-1)+1,猫统计!V:V,"<="&EOMONTH(A3,0))+SUMIFS(猫统计!AE:AE,猫统计!AB:AB,">="&EOMONTH(A3,-1)+1,猫统计!AB:AB,"<="&EOMONTH(A3,0))+SUMIFS(猫统计!AK:AK,猫统计!AH:AH,">="&EOMONTH(A3,-1)+1,猫统计!AH:AH,"<="&EOMONTH(A3,0))+SUMIFS(猫统计!AQ:AQ,猫统计!AN:AN,">="&EOMONTH(A3,-1)+1,猫统计!AN:AN,"<="&EOMONTH(A3,0))+SUMIFS(猫统计!AW:AW,猫统计!AT:AT,">="&EOMONTH(A3,-1)+1,猫统计!AT:AT,"<="&EOMONTH(A3,0))+SUMIFS(猫统计!BC:BC,猫统计!AZ:AZ,">="&EOMONTH(A3,-1)+1,猫统计!AZ:AZ,"<="&EOMONTH(A3,0))+SUMIFS(猫统计!BI:BI,猫统计!BF:BF,">="&EOMONTH(A3,-1)+1,猫统计!BF:BF,"<="&EOMONTH(A3,0))+SUMIFS(猫统计!BO:BO,猫统计!BL:BL,">="&EOMONTH(A3,-1)+1,猫统计!BL:BL,"<="&EOMONTH(A3,0)) -> 1
A4: 44075 | B4: =COUNTIFS(猫统计!J:J,">="&EOMONTH(A4,-1)+1,猫统计!J:J,"<="&EOMONTH(A4,0))+COUNTIFS(猫统计!P:P,">="&EOMONTH(A4,-1)+1,猫统计!P:P,"<="&EOMONTH(A4,0))+COUNTIFS(猫统计!V:V,">="&EOMONTH(A4,-1)+1,猫统计!V:V,"<="&EOMONTH(A4,0))+COUNTIFS(猫统计!AB:AB,">="&EOMONTH(A4,-1)+1,猫统计!AB:AB,"<="&EOMONTH(A4,0))+COUNTIFS(猫统计!AH:AH,">="&EOMONTH(A4,-1)+1,猫统计!AH:AH,"<="&EOMONTH(A4,0))+COUNTIFS(猫统计!AN:AN,">="&EOMONTH(A4,-1)+1,猫统计!AN:AN,"<="&EOMONTH(A4,0))+COUNTIFS(猫统计!AT:AT,">="&EOMONTH(A4,-1)+1,猫统计!AT:AT,"<="&EOMONTH(A4,0))+COUNTIFS(猫统计!AZ:AZ,">="&EOMONTH(A4,-1)+1,猫统计!AZ:AZ,"<="&EOMONTH(A4,0))+COUNTIFS(猫统计!BF:BF,">="&EOMONTH(A4,-1)+1,猫统计!BF:BF,"<="&EOMONTH(A4,0))+COUNTIFS(猫统计!BL:BL,">="&EOMONTH(A4,-1)+1,猫统计!BL:BL,"<="&EOMONTH(A4,0)) -> 1 | C4: =D4+E4 -> 3 | D4: =SUMIFS(猫统计!L:L,猫统计!J:J,">="&EOMONTH(A4,-1)+1,猫统计!J:J,"<="&EOMONTH(A4,0))+SUMIFS(猫统计!R:R,猫统计!P:P,">="&EOMONTH(A4,-1)+1,猫统计!P:P,"<="&EOMONTH(A4,0))+SUMIFS(猫统计!X:X,猫统计!V:V,">="&EOMONTH(A4,-1)+1,猫统计!V:V,"<="&EOMONTH(A4,0))+SUMIFS(猫统计!AD:AD,猫统计!AB:AB,">="&EOMONTH(A4,-1)+1,猫统计!AB:AB,"<="&EOMONTH(A4,0))+SUMIFS(猫统计!AJ:AJ,猫统计!AH:AH,">="&EOMONTH(A4,-1)+1,猫统计!AH:AH,"<="&EOMONTH(A4,0))+SUMIFS(猫统计!AP:AP,猫统计!AN:AN,">="&EOMONTH(A4,-1)+1,猫统计!AN:AN,"<="&EOMONTH(A4,0))+SUMIFS(猫统计!AV:AV,猫统计!AT:AT,">="&EOMONTH(A4,-1)+1,猫统计!AT:AT,"<="&EOMONTH(A4,0))+SUMIFS(猫统计!BB:BB,猫统计!AZ:AZ,">="&EOMONTH(A4,-1)+1,猫统计!AZ:AZ,"<="&EOMONTH(A4,0))+SUMIFS(猫统计!BH:BH,猫统计!BF:BF,">="&EOMONTH(A4,-1)+1,猫统计!BF:BF,"<="&EOMONTH(A4,0))+SUMIFS(猫统计!BN:BN,猫统计!BL:BL,">="&EOMONTH(A4,-1)+1,猫统计!BL:BL,"<="&EOMONTH(A4,0)) -> 0 | E4: =SUMIFS(猫统计!M:M,猫统计!J:J,">="&EOMONTH(A4,-1)+1,猫统计!J:J,"<="&EOMONTH(A4,0))+SUMIFS(猫统计!S:S,猫统计!P:P,">="&EOMONTH(A4,-1)+1,猫统计!P:P,"<="&EOMONTH(A4,0))+SUMIFS(猫统计!Y:Y,猫统计!V:V,">="&EOMONTH(A4,-1)+1,猫统计!V:V,"<="&EOMONTH(A4,0))+SUMIFS(猫统计!AE:AE,猫统计!AB:AB,">="&EOMONTH(A4,-1)+1,猫统计!AB:AB,"<="&EOMONTH(A4,0))+SUMIFS(猫统计!AK:AK,猫统计!AH:AH,">="&EOMONTH(A4,-1)+1,猫统计!AH:AH,"<="&EOMONTH(A4,0))+SUMIFS(猫统计!AQ:AQ,猫统计!AN:AN,">="&EOMONTH(A4,-1)+1,猫统计!AN:AN,"<="&EOMONTH(A4,0))+SUMIFS(猫统计!AW:AW,猫统计!AT:AT,">="&EOMONTH(A4,-1)+1,猫统计!AT:AT,"<="&EOMONTH(A4,0))+SUMIFS(猫统计!BC:BC,猫统计!AZ:AZ,">="&EOMONTH(A4,-1)+1,猫统计!AZ:AZ,"<="&EOMONTH(A4,0))+SUMIFS(猫统计!BI:BI,猫统计!BF:BF,">="&EOMONTH(A4,-1)+1,猫统计!BF:BF,"<="&EOMONTH(A4,0))+SUMIFS(猫统计!BO:BO,猫统计!BL:BL,">="&EOMONTH(A4,-1)+1,猫统计!BL:BL,"<="&EOMONTH(A4,0)) -> 3 | F4: =(E2+E3+E4)/(C2+C3+C4) -> 0.625 | G4: =(E2+E3+E4)/(B2+B3+B4) -> 1.6666667
A5: 44105 | B5: =COUNTIFS(猫统计!J:J,">="&EOMONTH(A5,-1)+1,猫统计!J:J,"<="&EOMONTH(A5,0))+COUNTIFS(猫统计!P:P,">="&EOMONTH(A5,-1)+1,猫统计!P:P,"<="&EOMONTH(A5,0))+COUNTIFS(猫统计!V:V,">="&EOMONTH(A5,-1)+1,猫统计!V:V,"<="&EOMONTH(A5,0))+COUNTIFS(猫统计!AB:AB,">="&EOMONTH(A5,-1)+1,猫统计!AB:AB,"<="&EOMONTH(A5,0))+COUNTIFS(猫统计!AH:AH,">="&EOMONTH(A5,-1)+1,猫统计!AH:AH,"<="&EOMONTH(A5,0))+COUNTIFS(猫统计!AN:AN,">="&EOMONTH(A5,-1)+1,猫统计!AN:AN,"<="&EOMONTH(A5,0))+COUNTIFS(猫统计!AT:AT,">="&EOMONTH(A5,-1)+1,猫统计!AT:AT,"<="&EOMONTH(A5,0))+COUNTIFS(猫统计!AZ:AZ,">="&EOMONTH(A5,-1)+1,猫统计!AZ:AZ,"<="&EOMONTH(A5,0))+COUNTIFS(猫统计!BF:BF,">="&EOMONTH(A5,-1)+1,猫统计!BF:BF,"<="&EOMONTH(A5,0))+COUNTIFS(猫统计!BL:BL,">="&EOMONTH(A5,-1)+1,猫统计!BL:BL,"<="&EOMONTH(A5,0)) -> 3 | C5: =D5+E5 -> 13 | D5: =SUMIFS(猫统计!L:L,猫统计!J:J,">="&EOMONTH(A5,-1)+1,猫统计!J:J,"<="&EOMONTH(A5,0))+SUMIFS(猫统计!R:R,猫统计!P:P,">="&EOMONTH(A5,-1)+1,猫统计!P:P,"<="&EOMONTH(A5,0))+SUMIFS(猫统计!X:X,猫统计!V:V,">="&EOMONTH(A5,-1)+1,猫统计!V:V,"<="&EOMONTH(A5,0))+SUMIFS(猫统计!AD:AD,猫统计!AB:AB,">="&EOMONTH(A5,-1)+1,猫统计!AB:AB,"<="&EOMONTH(A5,0))+SUMIFS(猫统计!AJ:AJ,猫统计!AH:AH,">="&EOMONTH(A5,-1)+1,猫统计!AH:AH,"<="&EOMONTH(A5,0))+SUMIFS(猫统计!AP:AP,猫统计!AN:AN,">="&EOMONTH(A5,-1)+1,猫统计!AN:AN,"<="&EOMONTH(A5,0))+SUMIFS(猫统计!AV:AV,猫统计!AT:AT,">="&EOMONTH(A5,-1)+1,猫统计!AT:AT,"<="&EOMONTH(A5,0))+SUMIFS(猫统计!BB:BB,猫统计!AZ:AZ,">="&EOMONTH(A5,-1)+1,猫统计!AZ:AZ,"<="&EOMONTH(A5,0))+SUMIFS(猫统计!BH:BH,猫统计!BF:BF,">="&EOMONTH(A5,-1)+1,猫统计!BF:BF,"<="&EOMONTH(A5,0))+SUMIFS(猫统计!BN:BN,猫统计!BL:BL,">="&EOMONTH(A5,-1)+1,猫统计!BL:BL,"<="&EOMONTH(A5,0)) -> 6 | E5: =SUMIFS(猫统计!M:M,猫统计!J:J,">="&EOMONTH(A5,-1)+1,猫统计!J:J,"<="&EOMONTH(A5,0))+SUMIFS(猫统计!S:S,猫统计!P:P,">="&EOMONTH(A5,-1)+1,猫统计!P:P,"<="&EOMONTH(A5,0))+SUMIFS(猫统计!Y:Y,猫统计!V:V,">="&EOMONTH(A5,-1)+1,猫统计!V:V,"<="&EOMONTH(A5,0))+SUMIFS(猫统计!AE:AE,猫统计!AB:AB,">="&EOMONTH(A5,-1)+1,猫统计!AB:AB,"<="&EOMONTH(A5,0))+SUMIFS(猫统计!AK:AK,猫统计!AH:AH,">="&EOMONTH(A5,-1)+1,猫统计!AH:AH,"<="&EOMONTH(A5,0))+SUMIFS(猫统计!AQ:AQ,猫统计!AN:AN,">="&EOMONTH(A5,-1)+1,猫统计!AN:AN,"<="&EOMONTH(A5,0))+SUMIFS(猫统计!AW:AW,猫统计!AT:AT,">="&EOMONTH(A5,-1)+1,猫统计!AT:AT,"<="&EOMONTH(A5,0))+SUMIFS(猫统计!BC:BC,猫统计!AZ:AZ,">="&EOMONTH(A5,-1)+1,猫统计!AZ:AZ,"<="&EOMONTH(A5,0))+SUMIFS(猫统计!BI:BI,猫统计!BF:BF,">="&EOMONTH(A5,-1)+1,猫统计!BF:BF,"<="&EOMONTH(A5,0))+SUMIFS(猫统计!BO:BO,猫统计!BL:BL,">="&EOMONTH(A5,-1)+1,猫统计!BL:BL,"<="&EOMONTH(A5,0)) -> 7
A6: 44136 | B6: =COUNTIFS(猫统计!J:J,">="&EOMONTH(A6,-1)+1,猫统计!J:J,"<="&EOMONTH(A6,0))+COUNTIFS(猫统计!P:P,">="&EOMONTH(A6,-1)+1,猫统计!P:P,"<="&EOMONTH(A6,0))+COUNTIFS(猫统计!V:V,">="&EOMONTH(A6,-1)+1,猫统计!V:V,"<="&EOMONTH(A6,0))+COUNTIFS(猫统计!AB:AB,">="&EOMONTH(A6,-1)+1,猫统计!AB:AB,"<="&EOMONTH(A6,0))+COUNTIFS(猫统计!AH:AH,">="&EOMONTH(A6,-1)+1,猫统计!AH:AH,"<="&EOMONTH(A6,0))+COUNTIFS(猫统计!AN:AN,">="&EOMONTH(A6,-1)+1,猫统计!AN:AN,"<="&EOMONTH(A6,0))+COUNTIFS(猫统计!AT:AT,">="&EOMONTH(A6,-1)+1,猫统计!AT:AT,"<="&EOMONTH(A6,0))+COUNTIFS(猫统计!AZ:AZ,">="&EOMONTH(A6,-1)+1,猫统计!AZ:AZ,"<="&EOMONTH(A6,0))+COUNTIFS(猫统计!BF:BF,">="&EOMONTH(A6,-1)+1,猫统计!BF:BF,"<="&EOMONTH(A6,0))+COUNTIFS(猫统计!BL:BL,">="&EOMONTH(A6,-1)+1,猫统计!BL:BL,"<="&EOMONTH(A6,0)) -> 0 | C6: =D6+E6 -> 0 | D6: =SUMIFS(猫统计!L:L,猫统计!J:J,">="&EOMONTH(A6,-1)+1,猫统计!J:J,"<="&EOMONTH(A6,0))+SUMIFS(猫统计!R:R,猫统计!P:P,">="&EOMONTH(A6,-1)+1,猫统计!P:P,"<="&EOMONTH(A6,0))+SUMIFS(猫统计!X:X,猫统计!V:V,">="&EOMONTH(A6,-1)+1,猫统计!V:V,"<="&EOMONTH(A6,0))+SUMIFS(猫统计!AD:AD,猫统计!AB:AB,">="&EOMONTH(A6,-1)+1,猫统计!AB:AB,"<="&EOMONTH(A6,0))+SUMIFS(猫统计!AJ:AJ,猫统计!AH:AH,">="&EOMONTH(A6,-1)+1,猫统计!AH:AH,"<="&EOMONTH(A6,0))+SUMIFS(猫统计!AP:AP,猫统计!AN:AN,">="&EOMONTH(A6,-1)+1,猫统计!AN:AN,"<="&EOMONTH(A6,0))+SUMIFS(猫统计!AV:AV,猫统计!AT:AT,">="&EOMONTH(A6,-1)+1,猫统计!AT:AT,"<="&EOMONTH(A6,0))+SUMIFS(猫统计!BB:BB,猫统计!AZ:AZ,">="&EOMONTH(A6,-1)+1,猫统计!AZ:AZ,"<="&EOMONTH(A6,0))+SUMIFS(猫统计!BH:BH,猫统计!BF:BF,">="&EOMONTH(A6,-1)+1,猫统计!BF:BF,"<="&EOMONTH(A6,0))+SUMIFS(猫统计!BN:BN,猫统计!BL:BL,">="&EOMONTH(A6,-1)+1,猫统计!BL:BL,"<="&EOMONTH(A6,0)) -> 0 | E6: =SUMIFS(猫统计!M:M,猫统计!J:J,">="&EOMONTH(A6,-1)+1,猫统计!J:J,"<="&EOMONTH(A6,0))+SUMIFS(猫统计!S:S,猫统计!P:P,">="&EOMONTH(A6,-1)+1,猫统计!P:P,"<="&EOMONTH(A6,0))+SUMIFS(猫统计!Y:Y,猫统计!V:V,">="&EOMONTH(A6,-1)+1,猫统计!V:V,"<="&EOMONTH(A6,0))+SUMIFS(猫统计!AE:AE,猫统计!AB:AB,">="&EOMONTH(A6,-1)+1,猫统计!AB:AB,"<="&EOMONTH(A6,0))+SUMIFS(猫统计!AK:AK,猫统计!AH:AH,">="&EOMONTH(A6,-1)+1,猫统计!AH:AH,"<="&EOMONTH(A6,0))+SUMIFS(猫统计!AQ:AQ,猫统计!AN:AN,">="&EOMONTH(A6,-1)+1,猫统计!AN:AN,"<="&EOMONTH(A6,0))+SUMIFS(猫统计!AW:AW,猫统计!AT:AT,">="&EOMONTH(A6,-1)+1,猫统计!AT:AT,"<="&EOMONTH(A6,0))+SUMIFS(猫统计!BC:BC,猫统计!AZ:AZ,">="&EOMONTH(A6,-1)+1,猫统计!AZ:AZ,"<="&EOMONTH(A6,0))+SUMIFS(猫统计!BI:BI,猫统计!BF:BF,">="&EOMONTH(A6,-1)+1,猫统计!BF:BF,"<="&EOMONTH(A6,0))+SUMIFS(猫统计!BO:BO,猫统计!BL:BL,">="&EOMONTH(A6,-1)+1,猫统计!BL:BL,"<="&EOMONTH(A6,0)) -> 0
A7: 44166 | B7: =COUNTIFS(猫统计!J:J,">="&EOMONTH(A7,-1)+1,猫统计!J:J,"<="&EOMONTH(A7,0))+COUNTIFS(猫统计!P:P,">="&EOMONTH(A7,-1)+1,猫统计!P:P,"<="&EOMONTH(A7,0))+COUNTIFS(猫统计!V:V,">="&EOMONTH(A7,-1)+1,猫统计!V:V,"<="&EOMONTH(A7,0))+COUNTIFS(猫统计!AB:AB,">="&EOMONTH(A7,-1)+1,猫统计!AB:AB,"<="&EOMONTH(A7,0))+COUNTIFS(猫统计!AH:AH,">="&EOMONTH(A7,-1)+1,猫统计!AH:AH,"<="&EOMONTH(A7,0))+COUNTIFS(猫统计!AN:AN,">="&EOMONTH(A7,-1)+1,猫统计!AN:AN,"<="&EOMONTH(A7,0))+COUNTIFS(猫统计!AT:AT,">="&EOMONTH(A7,-1)+1,猫统计!AT:AT,"<="&EOMONTH(A7,0))+COUNTIFS(猫统计!AZ:AZ,">="&EOMONTH(A7,-1)+1,猫统计!AZ:AZ,"<="&EOMONTH(A7,0))+COUNTIFS(猫统计!BF:BF,">="&EOMONTH(A7,-1)+1,猫统计!BF:BF,"<="&EOMONTH(A7,0))+COUNTIFS(猫统计!BL:BL,">="&EOMONTH(A7,-1)+1,猫统计!BL:BL,"<="&EOMONTH(A7,0)) -> 0 | C7: =D7+E7 -> 0 | D7: =SUMIFS(猫统计!L:L,猫统计!J:J,">="&EOMONTH(A7,-1)+1,猫统计!J:J,"<="&EOMONTH(A7,0))+SUMIFS(猫统计!R:R,猫统计!P:P,">="&EOMONTH(A7,-1)+1,猫统计!P:P,"<="&EOMONTH(A7,0))+SUMIFS(猫统计!X:X,猫统计!V:V,">="&EOMONTH(A7,-1)+1,猫统计!V:V,"<="&EOMONTH(A7,0))+SUMIFS(猫统计!AD:AD,猫统计!AB:AB,">="&EOMONTH(A7,-1)+1,猫统计!AB:AB,"<="&EOMONTH(A7,0))+SUMIFS(猫统计!AJ:AJ,猫统计!AH:AH,">="&EOMONTH(A7,-1)+1,猫统计!AH:AH,"<="&EOMONTH(A7,0))+SUMIFS(猫统计!AP:AP,猫统计!AN:AN,">="&EOMONTH(A7,-1)+1,猫统计!AN:AN,"<="&EOMONTH(A7,0))+SUMIFS(猫统计!AV:AV,猫统计!AT:AT,">="&EOMONTH(A7,-1)+1,猫统计!AT:AT,"<="&EOMONTH(A7,0))+SUMIFS(猫统计!BB:BB,猫统计!AZ:AZ,">="&EOMONTH(A7,-1)+1,猫统计!AZ:AZ,"<="&EOMONTH(A7,0))+SUMIFS(猫统计!BH:BH,猫统计!BF:BF,">="&EOMONTH(A7,-1)+1,猫统计!BF:BF,"<="&EOMONTH(A7,0))+SUMIFS(猫统计!BN:BN,猫统计!BL:BL,">="&EOMONTH(A7,-1)+1,猫统计!BL:BL,"<="&EOMONTH(A7,0)) -> 0 | E7: =SUMIFS(猫统计!M:M,猫统计!J:J,">="&EOMONTH(A7,-1)+1,猫统计!J:J,"<="&EOMONTH(A7,0))+SUMIFS(猫统计!S:S,猫统计!P:P,">="&EOMONTH(A7,-1)+1,猫统计!P:P,"<="&EOMONTH(A7,0))+SUMIFS(猫统计!Y:Y,猫统计!V:V,">="&EOMONTH(A7,-1)+1,猫统计!V:V,"<="&EOMONTH(A7,0))+SUMIFS(猫统计!AE:AE,猫统计!AB:AB,">="&EOMONTH(A7,-1)+1,猫统计!AB:AB,"<="&EOMONTH(A7,0))+SUMIFS(猫统计!AK:AK,猫统计!AH:AH,">="&EOMONTH(A7,-1)+1,猫统计!AH:AH,"<="&EOMONTH(A7,0))+SUMIFS(猫统计!AQ:AQ,猫统计!AN:AN,">="&EOMONTH(A7,-1)+1,猫统计!AN:AN,"<="&EOMONTH(A7,0))+SUMIFS(猫统计!AW:AW,猫统计!AT:AT,">="&EOMONTH(A7,-1)+1,猫统计!AT:AT,"<="&EOMONTH(A7,0))+SUMIFS(猫统计!BC:BC,猫统计!AZ:AZ,">="&EOMONTH(A7,-1)+1,猫统计!AZ:AZ,"<="&EOMONTH(A7,0))+SUMIFS(猫统计!BI:BI,猫统计!BF:BF,">="&EOMONTH(A7,-1)+1,猫统计!BF:BF,"<="&EOMONTH(A7,0))+SUMIFS(猫统计!BO:BO,猫统计!BL:BL,">="&EOMONTH(A7,-1)+1,猫统计!BL:BL,"<="&EOMONTH(A7,0)) -> 0 | F7: =(E5+E6+E7)/(C5+C6+C7) -> 0.53846154 | G7: =(E5+E6+E7)/(B5+B6+B7) -> 2.3333333
A8: 44197 | B8: =COUNTIFS(猫统计!J:J,">="&EOMONTH(A8,-1)+1,猫统计!J:J,"<="&EOMONTH(A8,0))+COUNTIFS(猫统计!P:P,">="&EOMONTH(A8,-1)+1,猫统计!P:P,"<="&EOMONTH(A8,0))+COUNTIFS(猫统计!V:V,">="&EOMONTH(A8,-1)+1,猫统计!V:V,"<="&EOMONTH(A8,0))+COUNTIFS(猫统计!AB:AB,">="&EOMONTH(A8,-1)+1,猫统计!AB:AB,"<="&EOMONTH(A8,0))+COUNTIFS(猫统计!AH:AH,">="&EOMONTH(A8,-1)+1,猫统计!AH:AH,"<="&EOMONTH(A8,0))+COUNTIFS(猫统计!AN:AN,">="&EOMONTH(A8,-1)+1,猫统计!AN:AN,"<="&EOMONTH(A8,0))+COUNTIFS(猫统计!AT:AT,">="&EOMONTH(A8,-1)+1,猫统计!AT:AT,"<="&EOMONTH(A8,0))+COUNTIFS(猫统计!AZ:AZ,">="&EOMONTH(A8,-1)+1,猫统计!AZ:AZ,"<="&EOMONTH(A8,0))+COUNTIFS(猫统计!BF:BF,">="&EOMONTH(A8,-1)+1,猫统计!BF:BF,"<="&EOMONTH(A8,0))+COUNTIFS(猫统计!BL:BL,">="&EOMONTH(A8,-1)+1,猫统计!BL:BL,"<="&EOMONTH(A8,0)) -> 3 | C8: =D8+E8 -> 11 | D8: =SUMIFS(猫统计!L:L,猫统计!J:J,">="&EOMONTH(A8,-1)+1,猫统计!J:J,"<="&EOMONTH(A8,0))+SUMIFS(猫统计!R:R,猫统计!P:P,">="&EOMONTH(A8,-1)+1,猫统计!P:P,"<="&EOMONTH(A8,0))+SUMIFS(猫统计!X:X,猫统计!V:V,">="&EOMONTH(A8,-1)+1,猫统计!V:V,"<="&EOMONTH(A8,0))+SUMIFS(猫统计!AD:AD,猫统计!AB:AB,">="&EOMONTH(A8,-1)+1,猫统计!AB:AB,"<="&EOMONTH(A8,0))+SUMIFS(猫统计!AJ:AJ,猫统计!AH:AH,">="&EOMONTH(A8,-1)+1,猫统计!AH:AH,"<="&EOMONTH(A8,0))+SUMIFS(猫统计!AP:AP,猫统计!AN:AN,">="&EOMONTH(A8,-1)+1,猫统计!AN:AN,"<="&EOMONTH(A8,0))+SUMIFS(猫统计!AV:AV,猫统计!AT:AT,">="&EOMONTH(A8,-1)+1,猫统计!AT:AT,"<="&EOMONTH(A8,0))+SUMIFS(猫统计!BB:BB,猫统计!AZ:AZ,">="&EOMONTH(A8,-1)+1,猫统计!AZ:AZ,"<="&EOMONTH(A8,0))+SUMIFS(猫统计!BH:BH,猫统计!BF:BF,">="&EOMONTH(A8,-1)+1,猫统计!BF:BF,"<="&EOMONTH(A8,0))+SUMIFS(猫统计!BN:BN,猫统计!BL:BL,">="&EOMONTH(A8,-1)+1,猫统计!BL:BL,"<="&EOMONTH(A8,0)) -> 2 | E8: =SUMIFS(猫统计!M:M,猫统计!J:J,">="&EOMONTH(A8,-1)+1,猫统计!J:J,"<="&EOMONTH(A8,0))+SUMIFS(猫统计!S:S,猫统计!P:P,">="&EOMONTH(A8,-1)+1,猫统计!P:P,"<="&EOMONTH(A8,0))+SUMIFS(猫统计!Y:Y,猫统计!V:V,">="&EOMONTH(A8,-1)+1,猫统计!V:V,"<="&EOMONTH(A8,0))+SUMIFS(猫统计!AE:AE,猫统计!AB:AB,">="&EOMONTH(A8,-1)+1,猫统计!AB:AB,"<="&EOMONTH(A8,0))+SUMIFS(猫统计!AK:AK,猫统计!AH:AH,">="&EOMONTH(A8,-1)+1,猫统计!AH:AH,"<="&EOMONTH(A8,0))+SUMIFS(猫统计!AQ:AQ,猫统计!AN:AN,">="&EOMONTH(A8,-1)+1,猫统计!AN:AN,"<="&EOMONTH(A8,0))+SUMIFS(猫统计!AW:AW,猫统计!AT:AT,">="&EOMONTH(A8,-1)+1,猫统计!AT:AT,"<="&EOMONTH(A8,0))+SUMIFS(猫统计!BC:BC,猫统计!AZ:AZ,">="&EOMONTH(A8,-1)+1,猫统计!AZ:AZ,"<="&EOMONTH(A8,0))+SUMIFS(猫统计!BI:BI,猫统计!BF:BF,">="&EOMONTH(A8,-1)+1,猫统计!BF:BF,"<="&EOMONTH(A8,0))+SUMIFS(猫统计!BO:BO,猫统计!BL:BL,">="&EOMONTH(A8,-1)+1,猫统计!BL:BL,"<="&EOMONTH(A8,0)) -> 9
A9: 44228 | B9: =COUNTIFS(猫统计!J:J,">="&EOMONTH(A9,-1)+1,猫统计!J:J,"<="&EOMONTH(A9,0))+COUNTIFS(猫统计!P:P,">="&EOMONTH(A9,-1)+1,猫统计!P:P,"<="&EOMONTH(A9,0))+COUNTIFS(猫统计!V:V,">="&EOMONTH(A9,-1)+1,猫统计!V:V,"<="&EOMONTH(A9,0))+COUNTIFS(猫统计!AB:AB,">="&EOMONTH(A9,-1)+1,猫统计!AB:AB,"<="&EOMONTH(A9,0))+COUNTIFS(猫统计!AH:AH,">="&EOMONTH(A9,-1)+1,猫统计!AH:AH,"<="&EOMONTH(A9,0))+COUNTIFS(猫统计!AN:AN,">="&EOMONTH(A9,-1)+1,猫统计!AN:AN,"<="&EOMONTH(A9,0))+COUNTIFS(猫统计!AT:AT,">="&EOMONTH(A9,-1)+1,猫统计!AT:AT,"<="&EOMONTH(A9,0))+COUNTIFS(猫统计!AZ:AZ,">="&EOMONTH(A9,-1)+1,猫统计!AZ:AZ,"<="&EOMONTH(A9,0))+COUNTIFS(猫统计!BF:BF,">="&EOMONTH(A9,-1)+1,猫统计!BF:BF,"<="&EOMONTH(A9,0))+COUNTIFS(猫统计!BL:BL,">="&EOMONTH(A9,-1)+1,猫统计!BL:BL,"<="&EOMONTH(A9,0)) -> 2 | C9: =D9+E9 -> 7 | D9: =SUMIFS(猫统计!L:L,猫统计!J:J,">="&EOMONTH(A9,-1)+1,猫统计!J:J,"<="&EOMONTH(A9,0))+SUMIFS(猫统计!R:R,猫统计!P:P,">="&EOMONTH(A9,-1)+1,猫统计!P:P,"<="&EOMONTH(A9,0))+SUMIFS(猫统计!X:X,猫统计!V:V,">="&EOMONTH(A9,-1)+1,猫统计!V:V,"<="&EOMONTH(A9,0))+SUMIFS(猫统计!AD:AD,猫统计!AB:AB,">="&EOMONTH(A9,-1)+1,猫统计!AB:AB,"<="&EOMONTH(A9,0))+SUMIFS(猫统计!AJ:AJ,猫统计!AH:AH,">="&EOMONTH(A9,-1)+1,猫统计!AH:AH,"<="&EOMONTH(A9,0))+SUMIFS(猫统计!AP:AP,猫统计!AN:AN,">="&EOMONTH(A9,-1)+1,猫统计!AN:AN,"<="&EOMONTH(A9,0))+SUMIFS(猫统计!AV:AV,猫统计!AT:AT,">="&EOMONTH(A9,-1)+1,猫统计!AT:AT,"<="&EOMONTH(A9,0))+SUMIFS(猫统计!BB:BB,猫统计!AZ:AZ,">="&EOMONTH(A9,-1)+1,猫统计!AZ:AZ,"<="&EOMONTH(A9,0))+SUMIFS(猫统计!BH:BH,猫统计!BF:BF,">="&EOMONTH(A9,-1)+1,猫统计!BF:BF,"<="&EOMONTH(A9,0))+SUMIFS(猫统计!BN:BN,猫统计!BL:BL,">="&EOMONTH(A9,-1)+1,猫统计!BL:BL,"<="&EOMONTH(A9,0)) -> 0 | E9: =SUMIFS(猫统计!M:M,猫统计!J:J,">="&EOMONTH(A9,-1)+1,猫统计!J:J,"<="&EOMONTH(A9,0))+SUMIFS(猫统计!S:S,猫统计!P:P,">="&EOMONTH(A9,-1)+1,猫统计!P:P,"<="&EOMONTH(A9,0))+SUMIFS(猫统计!Y:Y,猫统计!V:V,">="&EOMONTH(A9,-1)+1,猫统计!V:V,"<="&EOMONTH(A9,0))+SUMIFS(猫统计!AE:AE,猫统计!AB:AB,">="&EOMONTH(A9,-1)+1,猫统计!AB:AB,"<="&EOMONTH(A9,0))+SUMIFS(猫统计!AK:AK,猫统计!AH:AH,">="&EOMONTH(A9,-1)+1,猫统计!AH:AH,"<="&EOMONTH(A9,0))+SUMIFS(猫统计!AQ:AQ,猫统计!AN:AN,">="&EOMONTH(A9,-1)+1,猫统计!AN:AN,"<="&EOMONTH(A9,0))+SUMIFS(猫统计!AW:AW,猫统计!AT:AT,">="&EOMONTH(A9,-1)+1,猫统计!AT:AT,"<="&EOMONTH(A9,0))+SUMIFS(猫统计!BC:BC,猫统计!AZ:AZ,">="&EOMONTH(A9,-1)+1,猫统计!AZ:AZ,"<="&EOMONTH(A9,0))+SUMIFS(猫统计!BI:BI,猫统计!BF:BF,">="&EOMONTH(A9,-1)+1,猫统计!BF:BF,"<="&EOMONTH(A9,0))+SUMIFS(猫统计!BO:BO,猫统计!BL:BL,">="&EOMONTH(A9,-1)+1,猫统计!BL:BL,"<="&EOMONTH(A9,0)) -> 7
A10: 44256 | B10: =COUNTIFS(猫统计!J:J,">="&EOMONTH(A10,-1)+1,猫统计!J:J,"<="&EOMONTH(A10,0))+COUNTIFS(猫统计!P:P,">="&EOMONTH(A10,-1)+1,猫统计!P:P,"<="&EOMONTH(A10,0))+COUNTIFS(猫统计!V:V,">="&EOMONTH(A10,-1)+1,猫统计!V:V,"<="&EOMONTH(A10,0))+COUNTIFS(猫统计!AB:AB,">="&EOMONTH(A10,-1)+1,猫统计!AB:AB,"<="&EOMONTH(A10,0))+COUNTIFS(猫统计!AH:AH,">="&EOMONTH(A10,-1)+1,猫统计!AH:AH,"<="&EOMONTH(A10,0))+COUNTIFS(猫统计!AN:AN,">="&EOMONTH(A10,-1)+1,猫统计!AN:AN,"<="&EOMONTH(A10,0))+COUNTIFS(猫统计!AT:AT,">="&EOMONTH(A10,-1)+1,猫统计!AT:AT,"<="&EOMONTH(A10,0))+COUNTIFS(猫统计!AZ:AZ,">="&EOMONTH(A10,-1)+1,猫统计!AZ:AZ,"<="&EOMONTH(A10,0))+COUNTIFS(猫统计!BF:BF,">="&EOMONTH(A10,-1)+1,猫统计!BF:BF,"<="&EOMONTH(A10,0))+COUNTIFS(猫统计!BL:BL,">="&EOMONTH(A10,-1)+1,猫统计!BL:BL,"<="&EOMONTH(A10,0)) -> 8 | C10: =D10+E10 -> 33 | D10: =SUMIFS(猫统计!L:L,猫统计!J:J,">="&EOMONTH(A10,-1)+1,猫统计!J:J,"<="&EOMONTH(A10,0))+SUMIFS(猫统计!R:R,猫统计!P:P,">="&EOMONTH(A10,-1)+1,猫统计!P:P,"<="&EOMONTH(A10,0))+SUMIFS(猫统计!X:X,猫统计!V:V,">="&EOMONTH(A10,-1)+1,猫统计!V:V,"<="&EOMONTH(A10,0))+SUMIFS(猫统计!AD:AD,猫统计!AB:AB,">="&EOMONTH(A10,-1)+1,猫统计!AB:AB,"<="&EOMONTH(A10,0))+SUMIFS(猫统计!AJ:AJ,猫统计!AH:AH,">="&EOMONTH(A10,-1)+1,猫统计!AH:AH,"<="&EOMONTH(A10,0))+SUMIFS(猫统计!AP:AP,猫统计!AN:AN,">="&EOMONTH(A10,-1)+1,猫统计!AN:AN,"<="&EOMONTH(A10,0))+SUMIFS(猫统计!AV:AV,猫统计!AT:AT,">="&EOMONTH(A10,-1)+1,猫统计!AT:AT,"<="&EOMONTH(A10,0))+SUMIFS(猫统计!BB:BB,猫统计!AZ:AZ,">="&EOMONTH(A10,-1)+1,猫统计!AZ:AZ,"<="&EOMONTH(A10,0))+SUMIFS(猫统计!BH:BH,猫统计!BF:BF,">="&EOMONTH(A10,-1)+1,猫统计!BF:BF,"<="&EOMONTH(A10,0))+SUMIFS(猫统计!BN:BN,猫统计!BL:BL,">="&EOMONTH(A10,-1)+1,猫统计!BL:BL,"<="&EOMONTH(A10,0)) -> 9 | E10: =SUMIFS(猫统计!M:M,猫统计!J:J,">="&EOMONTH(A10,-1)+1,猫统计!J:J,"<="&EOMONTH(A10,0))+SUMIFS(猫统计!S:S,猫统计!P:P,">="&EOMONTH(A10,-1)+1,猫统计!P:P,"<="&EOMONTH(A10,0))+SUMIFS(猫统计!Y:Y,猫统计!V:V,">="&EOMONTH(A10,-1)+1,猫统计!V:V,"<="&EOMONTH(A10,0))+SUMIFS(猫统计!AE:AE,猫统计!AB:AB,">="&EOMONTH(A10,-1)+1,猫统计!AB:AB,"<="&EOMONTH(A10,0))+SUMIFS(猫统计!AK:AK,猫统计!AH:AH,">="&EOMONTH(A10,-1)+1,猫统计!AH:AH,"<="&EOMONTH(A10,0))+SUMIFS(猫统计!AQ:AQ,猫统计!AN:AN,">="&EOMONTH(A10,-1)+1,猫统计!AN:AN,"<="&EOMONTH(A10,0))+SUMIFS(猫统计!AW:AW,猫统计!AT:AT,">="&EOMONTH(A10,-1)+1,猫统计!AT:AT,"<="&EOMONTH(A10,0))+SUMIFS(猫统计!BC:BC,猫统计!AZ:AZ,">="&EOMONTH(A10,-1)+1,猫统计!AZ:AZ,"<="&EOMONTH(A10,0))+SUMIFS(猫统计!BI:BI,猫统计!BF:BF,">="&EOMONTH(A10,-1)+1,猫统计!BF:BF,"<="&EOMONTH(A10,0))+SUMIFS(猫统计!BO:BO,猫统计!BL:BL,">="&EOMONTH(A10,-1)+1,猫统计!BL:BL,"<="&EOMONTH(A10,0)) -> 24 | F10: =(E8+E9+E10)/(C8+C9+C10) -> 0.78431373 | G10: =(E8+E9+E10)/(B8+B9+B10) -> 3.0769231
A11: 44287 | B11: =COUNTIFS(猫统计!J:J,">="&EOMONTH(A11,-1)+1,猫统计!J:J,"<="&EOMONTH(A11,0))+COUNTIFS(猫统计!P:P,">="&EOMONTH(A11,-1)+1,猫统计!P:P,"<="&EOMONTH(A11,0))+COUNTIFS(猫统计!V:V,">="&EOMONTH(A11,-1)+1,猫统计!V:V,"<="&EOMONTH(A11,0))+COUNTIFS(猫统计!AB:AB,">="&EOMONTH(A11,-1)+1,猫统计!AB:AB,"<="&EOMONTH(A11,0))+COUNTIFS(猫统计!AH:AH,">="&EOMONTH(A11,-1)+1,猫统计!AH:AH,"<="&EOMONTH(A11,0))+COUNTIFS(猫统计!AN:AN,">="&EOMONTH(A11,-1)+1,猫统计!AN:AN,"<="&EOMONTH(A11,0))+COUNTIFS(猫统计!AT:AT,">="&EOMONTH(A11,-1)+1,猫统计!AT:AT,"<="&EOMONTH(A11,0))+COUNTIFS(猫统计!AZ:AZ,">="&EOMONTH(A11,-1)+1,猫统计!AZ:AZ,"<="&EOMONTH(A11,0))+COUNTIFS(猫统计!BF:BF,">="&EOMONTH(A11,-1)+1,猫统计!BF:BF,"<="&EOMONTH(A11,0))+COUNTIFS(猫统计!BL:BL,">="&EOMONTH(A11,-1)+1,猫统计!BL:BL,"<="&EOMONTH(A11,0)) -> 4 | C11: =D11+E11 -> 21 | D11: =SUMIFS(猫统计!L:L,猫统计!J:J,">="&EOMONTH(A11,-1)+1,猫统计!J:J,"<="&EOMONTH(A11,0))+SUMIFS(猫统计!R:R,猫统计!P:P,">="&EOMONTH(A11,-1)+1,猫统计!P:P,"<="&EOMONTH(A11,0))+SUMIFS(猫统计!X:X,猫统计!V:V,">="&EOMONTH(A11,-1)+1,猫统计!V:V,"<="&EOMONTH(A11,0))+SUMIFS(猫统计!AD:AD,猫统计!AB:AB,">="&EOMONTH(A11,-1)+1,猫统计!AB:AB,"<="&EOMONTH(A11,0))+SUMIFS(猫统计!AJ:AJ,猫统计!AH:AH,">="&EOMONTH(A11,-1)+1,猫统计!AH:AH,"<="&EOMONTH(A11,0))+SUMIFS(猫统计!AP:AP,猫统计!AN:AN,">="&EOMONTH(A11,-1)+1,猫统计!AN:AN,"<="&EOMONTH(A11,0))+SUMIFS(猫统计!AV:AV,猫统计!AT:AT,">="&EOMONTH(A11,-1)+1,猫统计!AT:AT,"<="&EOMONTH(A11,0))+SUMIFS(猫统计!BB:BB,猫统计!AZ:AZ,">="&EOMONTH(A11,-1)+1,猫统计!AZ:AZ,"<="&EOMONTH(A11,0))+SUMIFS(猫统计!BH:BH,猫统计!BF:BF,">="&EOMONTH(A11,-1)+1,猫统计!BF:BF,"<="&EOMONTH(A11,0))+SUMIFS(猫统计!BN:BN,猫统计!BL:BL,">="&EOMONTH(A11,-1)+1,猫统计!BL:BL,"<="&EOMONTH(A11,0)) -> 5 | E11: =SUMIFS(猫统计!M:M,猫统计!J:J,">="&EOMONTH(A11,-1)+1,猫统计!J:J,"<="&EOMONTH(A11,0))+SUMIFS(猫统计!S:S,猫统计!P:P,">="&EOMONTH(A11,-1)+1,猫统计!P:P,"<="&EOMONTH(A11,0))+SUMIFS(猫统计!Y:Y,猫统计!V:V,">="&EOMONTH(A11,-1)+1,猫统计!V:V,"<="&EOMONTH(A11,0))+SUMIFS(猫统计!AE:AE,猫统计!AB:AB,">="&EOMONTH(A11,-1)+1,猫统计!AB:AB,"<="&EOMONTH(A11,0))+SUMIFS(猫统计!AK:AK,猫统计!AH:AH,">="&EOMONTH(A11,-1)+1,猫统计!AH:AH,"<="&EOMONTH(A11,0))+SUMIFS(猫统计!AQ:AQ,猫统计!AN:AN,">="&EOMONTH(A11,-1)+1,猫统计!AN:AN,"<="&EOMONTH(A11,0))+SUMIFS(猫统计!AW:AW,猫统计!AT:AT,">="&EOMONTH(A11,-1)+1,猫统计!AT:AT,"<="&EOMONTH(A11,0))+SUMIFS(猫统计!BC:BC,猫统计!AZ:AZ,">="&EOMONTH(A11,-1)+1,猫统计!AZ:AZ,"<="&EOMONTH(A11,0))+SUMIFS(猫统计!BI:BI,猫统计!BF:BF,">="&EOMONTH(A11,-1)+1,猫统计!BF:BF,"<="&EOMONTH(A11,0))+SUMIFS(猫统计!BO:BO,猫统计!BL:BL,">="&EOMONTH(A11,-1)+1,猫统计!BL:BL,"<="&EOMONTH(A11,0)) -> 16
A12: 44317 | B12: =COUNTIFS(猫统计!J:J,">="&EOMONTH(A12,-1)+1,猫统计!J:J,"<="&EOMONTH(A12,0))+COUNTIFS(猫统计!P:P,">="&EOMONTH(A12,-1)+1,猫统计!P:P,"<="&EOMONTH(A12,0))+COUNTIFS(猫统计!V:V,">="&EOMONTH(A12,-1)+1,猫统计!V:V,"<="&EOMONTH(A12,0))+COUNTIFS(猫统计!AB:AB,">="&EOMONTH(A12,-1)+1,猫统计!AB:AB,"<="&EOMONTH(A12,0))+COUNTIFS(猫统计!AH:AH,">="&EOMONTH(A12,-1)+1,猫统计!AH:AH,"<="&EOMONTH(A12,0))+COUNTIFS(猫统计!AN:AN,">="&EOMONTH(A12,-1)+1,猫统计!AN:AN,"<="&EOMONTH(A12,0))+COUNTIFS(猫统计!AT:AT,">="&EOMONTH(A12,-1)+1,猫统计!AT:AT,"<="&EOMONTH(A12,0))+COUNTIFS(猫统计!AZ:AZ,">="&EOMONTH(A12,-1)+1,猫统计!AZ:AZ,"<="&EOMONTH(A12,0))+COUNTIFS(猫统计!BF:BF,">="&EOMONTH(A12,-1)+1,猫统计!BF:BF,"<="&EOMONTH(A12,0))+COUNTIFS(猫统计!BL:BL,">="&EOMONTH(A12,-1)+1,猫统计!BL:BL,"<="&EOMONTH(A12,0)) -> 3 | C12: =D12+E12 -> 9 | D12: =SUMIFS(猫统计!L:L,猫统计!J:J,">="&EOMONTH(A12,-1)+1,猫统计!J:J,"<="&EOMONTH(A12,0))+SUMIFS(猫统计!R:R,猫统计!P:P,">="&EOMONTH(A12,-1)+1,猫统计!P:P,"<="&EOMONTH(A12,0))+SUMIFS(猫统计!X:X,猫统计!V:V,">="&EOMONTH(A12,-1)+1,猫统计!V:V,"<="&EOMONTH(A12,0))+SUMIFS(猫统计!AD:AD,猫统计!AB:AB,">="&EOMONTH(A12,-1)+1,猫统计!AB:AB,"<="&EOMONTH(A12,0))+SUMIFS(猫统计!AJ:AJ,猫统计!AH:AH,">="&EOMONTH(A12,-1)+1,猫统计!AH:AH,"<="&EOMONTH(A12,0))+SUMIFS(猫统计!AP:AP,猫统计!AN:AN,">="&EOMONTH(A12,-1)+1,猫统计!AN:AN,"<="&EOMONTH(A12,0))+SUMIFS(猫统计!AV:AV,猫统计!AT:AT,">="&EOMONTH(A12,-1)+1,猫统计!AT:AT,"<="&EOMONTH(A12,0))+SUMIFS(猫统计!BB:BB,猫统计!AZ:AZ,">="&EOMONTH(A12,-1)+1,猫统计!AZ:AZ,"<="&EOMONTH(A12,0))+SUMIFS(猫统计!BH:BH,猫统计!BF:BF,">="&EOMONTH(A12,-1)+1,猫统计!BF:BF,"<="&EOMONTH(A12,0))+SUMIFS(猫统计!BN:BN,猫统计!BL:BL,">="&EOMONTH(A12,-1)+1,猫统计!BL:BL,"<="&EOMONTH(A12,0)) -> 4 | E12: =SUMIFS(猫统计!M:M,猫统计!J:J,">="&EOMONTH(A12,-1)+1,猫统计!J:J,"<="&EOMONTH(A12,0))+SUMIFS(猫统计!S:S,猫统计!P:P,">="&EOMONTH(A12,-1)+1,猫统计!P:P,"<="&EOMONTH(A12,0))+SUMIFS(猫统计!Y:Y,猫统计!V:V,">="&EOMONTH(A12,-1)+1,猫统计!V:V,"<="&EOMONTH(A12,0))+SUMIFS(猫统计!AE:AE,猫统计!AB:AB,">="&EOMONTH(A12,-1)+1,猫统计!AB:AB,"<="&EOMONTH(A12,0))+SUMIFS(猫统计!AK:AK,猫统计!AH:AH,">="&EOMONTH(A12,-1)+1,猫统计!AH:AH,"<="&EOMONTH(A12,0))+SUMIFS(猫统计!AQ:AQ,猫统计!AN:AN,">="&EOMONTH(A12,-1)+1,猫统计!AN:AN,"<="&EOMONTH(A12,0))+SUMIFS(猫统计!AW:AW,猫统计!AT:AT,">="&EOMONTH(A12,-1)+1,猫统计!AT:AT,"<="&EOMONTH(A12,0))+SUMIFS(猫统计!BC:BC,猫统计!AZ:AZ,">="&EOMONTH(A12,-1)+1,猫统计!AZ:AZ,"<="&EOMONTH(A12,0))+SUMIFS(猫统计!BI:BI,猫统计!BF:BF,">="&EOMONTH(A12,-1)+1,猫统计!BF:BF,"<="&EOMONTH(A12,0))+SUMIFS(猫统计!BO:BO,猫统计!BL:BL,">="&EOMONTH(A12,-1)+1,猫统计!BL:BL,"<="&EOMONTH(A12,0)) -> 5
A13: 44348 | B13: =COUNTIFS(猫统计!J:J,">="&EOMONTH(A13,-1)+1,猫统计!J:J,"<="&EOMONTH(A13,0))+COUNTIFS(猫统计!P:P,">="&EOMONTH(A13,-1)+1,猫统计!P:P,"<="&EOMONTH(A13,0))+COUNTIFS(猫统计!V:V,">="&EOMONTH(A13,-1)+1,猫统计!V:V,"<="&EOMONTH(A13,0))+COUNTIFS(猫统计!AB:AB,">="&EOMONTH(A13,-1)+1,猫统计!AB:AB,"<="&EOMONTH(A13,0))+COUNTIFS(猫统计!AH:AH,">="&EOMONTH(A13,-1)+1,猫统计!AH:AH,"<="&EOMONTH(A13,0))+COUNTIFS(猫统计!AN:AN,">="&EOMONTH(A13,-1)+1,猫统计!AN:AN,"<="&EOMONTH(A13,0))+COUNTIFS(猫统计!AT:AT,">="&EOMONTH(A13,-1)+1,猫统计!AT:AT,"<="&EOMONTH(A13,0))+COUNTIFS(猫统计!AZ:AZ,">="&EOMONTH(A13,-1)+1,猫统计!AZ:AZ,"<="&EOMONTH(A13,0))+COUNTIFS(猫统计!BF:BF,">="&EOMONTH(A13,-1)+1,猫统计!BF:BF,"<="&EOMONTH(A13,0))+COUNTIFS(猫统计!BL:BL,">="&EOMONTH(A13,-1)+1,猫统计!BL:BL,"<="&EOMONTH(A13,0)) -> 0 | C13: =D13+E13 -> 0 | D13: =SUMIFS(猫统计!L:L,猫统计!J:J,">="&EOMONTH(A13,-1)+1,猫统计!J:J,"<="&EOMONTH(A13,0))+SUMIFS(猫统计!R:R,猫统计!P:P,">="&EOMONTH(A13,-1)+1,猫统计!P:P,"<="&EOMONTH(A13,0))+SUMIFS(猫统计!X:X,猫统计!V:V,">="&EOMONTH(A13,-1)+1,猫统计!V:V,"<="&EOMONTH(A13,0))+SUMIFS(猫统计!AD:AD,猫统计!AB:AB,">="&EOMONTH(A13,-1)+1,猫统计!AB:AB,"<="&EOMONTH(A13,0))+SUMIFS(猫统计!AJ:AJ,猫统计!AH:AH,">="&EOMONTH(A13,-1)+1,猫统计!AH:AH,"<="&EOMONTH(A13,0))+SUMIFS(猫统计!AP:AP,猫统计!AN:AN,">="&EOMONTH(A13,-1)+1,猫统计!AN:AN,"<="&EOMONTH(A13,0))+SUMIFS(猫统计!AV:AV,猫统计!AT:AT,">="&EOMONTH(A13,-1)+1,猫统计!AT:AT,"<="&EOMONTH(A13,0))+SUMIFS(猫统计!BB:BB,猫统计!AZ:AZ,">="&EOMONTH(A13,-1)+1,猫统计!AZ:AZ,"<="&EOMONTH(A13,0))+SUMIFS(猫统计!BH:BH,猫统计!BF:BF,">="&EOMONTH(A13,-1)+1,猫统计!BF:BF,"<="&EOMONTH(A13,0))+SUMIFS(猫统计!BN:BN,猫统计!BL:BL,">="&EOMONTH(A13,-1)+1,猫统计!BL:BL,"<="&EOMONTH(A13,0)) -> 0 | E13: =SUMIFS(猫统计!M:M,猫统计!J:J,">="&EOMONTH(A13,-1)+1,猫统计!J:J,"<="&EOMONTH(A13,0))+SUMIFS(猫统计!S:S,猫统计!P:P,">="&EOMONTH(A13,-1)+1,猫统计!P:P,"<="&EOMONTH(A13,0))+SUMIFS(猫统计!Y:Y,猫统计!V:V,">="&EOMONTH(A13,-1)+1,猫统计!V:V,"<="&EOMONTH(A13,0))+SUMIFS(猫统计!AE:AE,猫统计!AB:AB,">="&EOMONTH(A13,-1)+1,猫统计!AB:AB,"<="&EOMONTH(A13,0))+SUMIFS(猫统计!AK:AK,猫统计!AH:AH,">="&EOMONTH(A13,-1)+1,猫统计!AH:AH,"<="&EOMONTH(A13,0))+SUMIFS(猫统计!AQ:AQ,猫统计!AN:AN,">="&EOMONTH(A13,-1)+1,猫统计!AN:AN,"<="&EOMONTH(A13,0))+SUMIFS(猫统计!AW:AW,猫统计!AT:AT,">="&EOMONTH(A13,-1)+1,猫统计!AT:AT,"<="&EOMONTH(A13,0))+SUMIFS(猫统计!BC:BC,猫统计!AZ:AZ,">="&EOMONTH(A13,-1)+1,猫统计!AZ:AZ,"<="&EOMONTH(A13,0))+SUMIFS(猫统计!BI:BI,猫统计!BF:BF,">="&EOMONTH(A13,-1)+1,猫统计!BF:BF,"<="&EOMONTH(A13,0))+SUMIFS(猫统计!BO:BO,猫统计!BL:BL,">="&EOMONTH(A13,-1)+1,猫统计!BL:BL,"<="&EOMONTH(A13,0)) -> 0 | F13: =(E11+E12+E13)/(C11+C12+C13) -> 0.7 | G13: =(E11+E12+E13)/(B11+B12+B13) -> 3
A14: 44378 | B14: =COUNTIFS(猫统计!J:J,">="&EOMONTH(A14,-1)+1,猫统计!J:J,"<="&EOMONTH(A14,0))+COUNTIFS(猫统计!P:P,">="&EOMONTH(A14,-1)+1,猫统计!P:P,"<="&EOMONTH(A14,0))+COUNTIFS(猫统计!V:V,">="&EOMONTH(A14,-1)+1,猫统计!V:V,"<="&EOMONTH(A14,0))+COUNTIFS(猫统计!AB:AB,">="&EOMONTH(A14,-1)+1,猫统计!AB:AB,"<="&EOMONTH(A14,0))+COUNTIFS(猫统计!AH:AH,">="&EOMONTH(A14,-1)+1,猫统计!AH:AH,"<="&EOMONTH(A14,0))+COUNTIFS(猫统计!AN:AN,">="&EOMONTH(A14,-1)+1,猫统计!AN:AN,"<="&EOMONTH(A14,0))+COUNTIFS(猫统计!AT:AT,">="&EOMONTH(A14,-1)+1,猫统计!AT:AT,"<="&EOMONTH(A14,0))+COUNTIFS(猫统计!AZ:AZ,">="&EOMONTH(A14,-1)+1,猫统计!AZ:AZ,"<="&EOMONTH(A14,0))+COUNTIFS(猫统计!BF:BF,">="&EOMONTH(A14,-1)+1,猫统计!BF:BF,"<="&EOMONTH(A14,0))+COUNTIFS(猫统计!BL:BL,">="&EOMONTH(A14,-1)+1,猫统计!BL:BL,"<="&EOMONTH(A14,0)) -> 6 | C14: =D14+E14 -> 26 | D14: =SUMIFS(猫统计!L:L,猫统计!J:J,">="&EOMONTH(A14,-1)+1,猫统计!J:J,"<="&EOMONTH(A14,0))+SUMIFS(猫统计!R:R,猫统计!P:P,">="&EOMONTH(A14,-1)+1,猫统计!P:P,"<="&EOMONTH(A14,0))+SUMIFS(猫统计!X:X,猫统计!V:V,">="&EOMONTH(A14,-1)+1,猫统计!V:V,"<="&EOMONTH(A14,0))+SUMIFS(猫统计!AD:AD,猫统计!AB:AB,">="&EOMONTH(A14,-1)+1,猫统计!AB:AB,"<="&EOMONTH(A14,0))+SUMIFS(猫统计!AJ:AJ,猫统计!AH:AH,">="&EOMONTH(A14,-1)+1,猫统计!AH:AH,"<="&EOMONTH(A14,0))+SUMIFS(猫统计!AP:AP,猫统计!AN:AN,">="&EOMONTH(A14,-1)+1,猫统计!AN:AN,"<="&EOMONTH(A14,0))+SUMIFS(猫统计!AV:AV,猫统计!AT:AT,">="&EOMONTH(A14,-1)+1,猫统计!AT:AT,"<="&EOMONTH(A14,0))+SUMIFS(猫统计!BB:BB,猫统计!AZ:AZ,">="&EOMONTH(A14,-1)+1,猫统计!AZ:AZ,"<="&EOMONTH(A14,0))+SUMIFS(猫统计!BH:BH,猫统计!BF:BF,">="&EOMONTH(A14,-1)+1,猫统计!BF:BF,"<="&EOMONTH(A14,0))+SUMIFS(猫统计!BN:BN,猫统计!BL:BL,">="&EOMONTH(A14,-1)+1,猫统计!BL:BL,"<="&EOMONTH(A14,0)) -> 6 | E14: =SUMIFS(猫统计!M:M,猫统计!J:J,">="&EOMONTH(A14,-1)+1,猫统计!J:J,"<="&EOMONTH(A14,0))+SUMIFS(猫统计!S:S,猫统计!P:P,">="&EOMONTH(A14,-1)+1,猫统计!P:P,"<="&EOMONTH(A14,0))+SUMIFS(猫统计!Y:Y,猫统计!V:V,">="&EOMONTH(A14,-1)+1,猫统计!V:V,"<="&EOMONTH(A14,0))+SUMIFS(猫统计!AE:AE,猫统计!AB:AB,">="&EOMONTH(A14,-1)+1,猫统计!AB:AB,"<="&EOMONTH(A14,0))+SUMIFS(猫统计!AK:AK,猫统计!AH:AH,">="&EOMONTH(A14,-1)+1,猫统计!AH:AH,"<="&EOMONTH(A14,0))+SUMIFS(猫统计!AQ:AQ,猫统计!AN:AN,">="&EOMONTH(A14,-1)+1,猫统计!AN:AN,"<="&EOMONTH(A14,0))+SUMIFS(猫统计!AW:AW,猫统计!AT:AT,">="&EOMONTH(A14,-1)+1,猫统计!AT:AT,"<="&EOMONTH(A14,0))+SUMIFS(猫统计!BC:BC,猫统计!AZ:AZ,">="&EOMONTH(A14,-1)+1,猫统计!AZ:AZ,"<="&EOMONTH(A14,0))+SUMIFS(猫统计!BI:BI,猫统计!BF:BF,">="&EOMONTH(A14,-1)+1,猫统计!BF:BF,"<="&EOMONTH(A14,0))+SUMIFS(猫统计!BO:BO,猫统计!BL:BL,">="&EOMONTH(A14,-1)+1,猫统计!BL:BL,"<="&EOMONTH(A14,0)) -> 20
A15: 44409 | B15: =COUNTIFS(猫统计!J:J,">="&EOMONTH(A15,-1)+1,猫统计!J:J,"<="&EOMONTH(A15,0))+COUNTIFS(猫统计!P:P,">="&EOMONTH(A15,-1)+1,猫统计!P:P,"<="&EOMONTH(A15,0))+COUNTIFS(猫统计!V:V,">="&EOMONTH(A15,-1)+1,猫统计!V:V,"<="&EOMONTH(A15,0))+COUNTIFS(猫统计!AB:AB,">="&EOMONTH(A15,-1)+1,猫统计!AB:AB,"<="&EOMONTH(A15,0))+COUNTIFS(猫统计!AH:AH,">="&EOMONTH(A15,-1)+1,猫统计!AH:AH,"<="&EOMONTH(A15,0))+COUNTIFS(猫统计!AN:AN,">="&EOMONTH(A15,-1)+1,猫统计!AN:AN,"<="&EOMONTH(A15,0))+COUNTIFS(猫统计!AT:AT,">="&EOMONTH(A15,-1)+1,猫统计!AT:AT,"<="&EOMONTH(A15,0))+COUNTIFS(猫统计!AZ:AZ,">="&EOMONTH(A15,-1)+1,猫统计!AZ:AZ,"<="&EOMONTH(A15,0))+COUNTIFS(猫统计!BF:BF,">="&EOMONTH(A15,-1)+1,猫统计!BF:BF,"<="&EOMONTH(A15,0))+COUNTIFS(猫统计!BL:BL,">="&EOMONTH(A15,-1)+1,猫统计!BL:BL,"<="&EOMONTH(A15,0)) -> 3 | C15: =D15+E15 -> 15 | D15: =SUMIFS(猫统计!L:L,猫统计!J:J,">="&EOMONTH(A15,-1)+1,猫统计!J:J,"<="&EOMONTH(A15,0))+SUMIFS(猫统计!R:R,猫统计!P:P,">="&EOMONTH(A15,-1)+1,猫统计!P:P,"<="&EOMONTH(A15,0))+SUMIFS(猫统计!X:X,猫统计!V:V,">="&EOMONTH(A15,-1)+1,猫统计!V:V,"<="&EOMONTH(A15,0))+SUMIFS(猫统计!AD:AD,猫统计!AB:AB,">="&EOMONTH(A15,-1)+1,猫统计!AB:AB,"<="&EOMONTH(A15,0))+SUMIFS(猫统计!AJ:AJ,猫统计!AH:AH,">="&EOMONTH(A15,-1)+1,猫统计!AH:AH,"<="&EOMONTH(A15,0))+SUMIFS(猫统计!AP:AP,猫统计!AN:AN,">="&EOMONTH(A15,-1)+1,猫统计!AN:AN,"<="&EOMONTH(A15,0))+SUMIFS(猫统计!AV:AV,猫统计!AT:AT,">="&EOMONTH(A15,-1)+1,猫统计!AT:AT,"<="&EOMONTH(A15,0))+SUMIFS(猫统计!BB:BB,猫统计!AZ:AZ,">="&EOMONTH(A15,-1)+1,猫统计!AZ:AZ,"<="&EOMONTH(A15,0))+SUMIFS(猫统计!BH:BH,猫统计!BF:BF,">="&EOMONTH(A15,-1)+1,猫统计!BF:BF,"<="&EOMONTH(A15,0))+SUMIFS(猫统计!BN:BN,猫统计!BL:BL,">="&EOMONTH(A15,-1)+1,猫统计!BL:BL,"<="&EOMONTH(A15,0)) -> 0 | E15: =SUMIFS(猫统计!M:M,猫统计!J:J,">="&EOMONTH(A15,-1)+1,猫统计!J:J,"<="&EOMONTH(A15,0))+SUMIFS(猫统计!S:S,猫统计!P:P,">="&EOMONTH(A15,-1)+1,猫统计!P:P,"<="&EOMONTH(A15,0))+SUMIFS(猫统计!Y:Y,猫统计!V:V,">="&EOMONTH(A15,-1)+1,猫统计!V:V,"<="&EOMONTH(A15,0))+SUMIFS(猫统计!AE:AE,猫统计!AB:AB,">="&EOMONTH(A15,-1)+1,猫统计!AB:AB,"<="&EOMONTH(A15,0))+SUMIFS(猫统计!AK:AK,猫统计!AH:AH,">="&EOMONTH(A15,-1)+1,猫统计!AH:AH,"<="&EOMONTH(A15,0))+SUMIFS(猫统计!AQ:AQ,猫统计!AN:AN,">="&EOMONTH(A15,-1)+1,猫统计!AN:AN,"<="&EOMONTH(A15,0))+SUMIFS(猫统计!AW:AW,猫统计!AT:AT,">="&EOMONTH(A15,-1)+1,猫统计!AT:AT,"<="&EOMONTH(A15,0))+SUMIFS(猫统计!BC:BC,猫统计!AZ:AZ,">="&EOMONTH(A15,-1)+1,猫统计!AZ:AZ,"<="&EOMONTH(A15,0))+SUMIFS(猫统计!BI:BI,猫统计!BF:BF,">="&EOMONTH(A15,-1)+1,猫统计!BF:BF,"<="&EOMONTH(A15,0))+SUMIFS(猫统计!BO:BO,猫统计!BL:BL,">="&EOMONTH(A15,-1)+1,猫统计!BL:BL,"<="&EOMONTH(A15,0)) -> 15
A16: 44440 | B16: =COUNTIFS(猫统计!J:J,">="&EOMONTH(A16,-1)+1,猫统计!J:J,"<="&EOMONTH(A16,0))+COUNTIFS(猫统计!P:P,">="&EOMONTH(A16,-1)+1,猫统计!P:P,"<="&EOMONTH(A16,0))+COUNTIFS(猫统计!V:V,">="&EOMONTH(A16,-1)+1,猫统计!V:V,"<="&EOMONTH(A16,0))+COUNTIFS(猫统计!AB:AB,">="&EOMONTH(A16,-1)+1,猫统计!AB:AB,"<="&EOMONTH(A16,0))+COUNTIFS(猫统计!AH:AH,">="&EOMONTH(A16,-1)+1,猫统计!AH:AH,"<="&EOMONTH(A16,0))+COUNTIFS(猫统计!AN:AN,">="&EOMONTH(A16,-1)+1,猫统计!AN:AN,"<="&EOMONTH(A16,0))+COUNTIFS(猫统计!AT:AT,">="&EOMONTH(A16,-1)+1,猫统计!AT:AT,"<="&EOMONTH(A16,0))+COUNTIFS(猫统计!AZ:AZ,">="&EOMONTH(A16,-1)+1,猫统计!AZ:AZ,"<="&EOMONTH(A16,0))+COUNTIFS(猫统计!BF:BF,">="&EOMONTH(A16,-1)+1,猫统计!BF:BF,"<="&EOMONTH(A16,0))+COUNTIFS(猫统计!BL:BL,">="&EOMONTH(A16,-1)+1,猫统计!BL:BL,"<="&EOMONTH(A16,0)) -> 5 | C16: =D16+E16 -> 20 | D16: =SUMIFS(猫统计!L:L,猫统计!J:J,">="&EOMONTH(A16,-1)+1,猫统计!J:J,"<="&EOMONTH(A16,0))+SUMIFS(猫统计!R:R,猫统计!P:P,">="&EOMONTH(A16,-1)+1,猫统计!P:P,"<="&EOMONTH(A16,0))+SUMIFS(猫统计!X:X,猫统计!V:V,">="&EOMONTH(A16,-1)+1,猫统计!V:V,"<="&EOMONTH(A16,0))+SUMIFS(猫统计!AD:AD,猫统计!AB:AB,">="&EOMONTH(A16,-1)+1,猫统计!AB:AB,"<="&EOMONTH(A16,0))+SUMIFS(猫统计!AJ:AJ,猫统计!AH:AH,">="&EOMONTH(A16,-1)+1,猫统计!AH:AH,"<="&EOMONTH(A16,0))+SUMIFS(猫统计!AP:AP,猫统计!AN:AN,">="&EOMONTH(A16,-1)+1,猫统计!AN:AN,"<="&EOMONTH(A16,0))+SUMIFS(猫统计!AV:AV,猫统计!AT:AT,">="&EOMONTH(A16,-1)+1,猫统计!AT:AT,"<="&EOMONTH(A16,0))+SUMIFS(猫统计!BB:BB,猫统计!AZ:AZ,">="&EOMONTH(A16,-1)+1,猫统计!AZ:AZ,"<="&EOMONTH(A16,0))+SUMIFS(猫统计!BH:BH,猫统计!BF:BF,">="&EOMONTH(A16,-1)+1,猫统计!BF:BF,"<="&EOMONTH(A16,0))+SUMIFS(猫统计!BN:BN,猫统计!BL:BL,">="&EOMONTH(A16,-1)+1,猫统计!BL:BL,"<="&EOMONTH(A16,0)) -> 4 | E16: =SUMIFS(猫统计!M:M,猫统计!J:J,">="&EOMONTH(A16,-1)+1,猫统计!J:J,"<="&EOMONTH(A16,0))+SUMIFS(猫统计!S:S,猫统计!P:P,">="&EOMONTH(A16,-1)+1,猫统计!P:P,"<="&EOMONTH(A16,0))+SUMIFS(猫统计!Y:Y,猫统计!V:V,">="&EOMONTH(A16,-1)+1,猫统计!V:V,"<="&EOMONTH(A16,0))+SUMIFS(猫统计!AE:AE,猫统计!AB:AB,">="&EOMONTH(A16,-1)+1,猫统计!AB:AB,"<="&EOMONTH(A16,0))+SUMIFS(猫统计!AK:AK,猫统计!AH:AH,">="&EOMONTH(A16,-1)+1,猫统计!AH:AH,"<="&EOMONTH(A16,0))+SUMIFS(猫统计!AQ:AQ,猫统计!AN:AN,">="&EOMONTH(A16,-1)+1,猫统计!AN:AN,"<="&EOMONTH(A16,0))+SUMIFS(猫统计!AW:AW,猫统计!AT:AT,">="&EOMONTH(A16,-1)+1,猫统计!AT:AT,"<="&EOMONTH(A16,0))+SUMIFS(猫统计!BC:BC,猫统计!AZ:AZ,">="&EOMONTH(A16,-1)+1,猫统计!AZ:AZ,"<="&EOMONTH(A16,0))+SUMIFS(猫统计!BI:BI,猫统计!BF:BF,">="&EOMONTH(A16,-1)+1,猫统计!BF:BF,"<="&EOMONTH(A16,0))+SUMIFS(猫统计!BO:BO,猫统计!BL:BL,">="&EOMONTH(A16,-1)+1,猫统计!BL:BL,"<="&EOMONTH(A16,0)) -> 16 | F16: =(E14+E15+E16)/(C14+C15+C16) -> 0.83606557 | G16: =(E14+E15+E16)/(B14+B15+B16) -> 3.6428571
A17: 44470 | B17: =COUNTIFS(猫统计!J:J,">="&EOMONTH(A17,-1)+1,猫统计!J:J,"<="&EOMONTH(A17,0))+COUNTIFS(猫统计!P:P,">="&EOMONTH(A17,-1)+1,猫统计!P:P,"<="&EOMONTH(A17,0))+COUNTIFS(猫统计!V:V,">="&EOMONTH(A17,-1)+1,猫统计!V:V,"<="&EOMONTH(A17,0))+COUNTIFS(猫统计!AB:AB,">="&EOMONTH(A17,-1)+1,猫统计!AB:AB,"<="&EOMONTH(A17,0))+COUNTIFS(猫统计!AH:AH,">="&EOMONTH(A17,-1)+1,猫统计!AH:AH,"<="&EOMONTH(A17,0))+COUNTIFS(猫统计!AN:AN,">="&EOMONTH(A17,-1)+1,猫统计!AN:AN,"<="&EOMONTH(A17,0))+COUNTIFS(猫统计!AT:AT,">="&EOMONTH(A17,-1)+1,猫统计!AT:AT,"<="&EOMONTH(A17,0))+COUNTIFS(猫统计!AZ:AZ,">="&EOMONTH(A17,-1)+1,猫统计!AZ:AZ,"<="&EOMONTH(A17,0))+COUNTIFS(猫统计!BF:BF,">="&EOMONTH(A17,-1)+1,猫统计!BF:BF,"<="&EOMONTH(A17,0))+COUNTIFS(猫统计!BL:BL,">="&EOMONTH(A17,-1)+1,猫统计!BL:BL,"<="&EOMONTH(A17,0)) -> 3 | C17: =D17+E17 -> 17 | D17: =SUMIFS(猫统计!L:L,猫统计!J:J,">="&EOMONTH(A17,-1)+1,猫统计!J:J,"<="&EOMONTH(A17,0))+SUMIFS(猫统计!R:R,猫统计!P:P,">="&EOMONTH(A17,-1)+1,猫统计!P:P,"<="&EOMONTH(A17,0))+SUMIFS(猫统计!X:X,猫统计!V:V,">="&EOMONTH(A17,-1)+1,猫统计!V:V,"<="&EOMONTH(A17,0))+SUMIFS(猫统计!AD:AD,猫统计!AB:AB,">="&EOMONTH(A17,-1)+1,猫统计!AB:AB,"<="&EOMONTH(A17,0))+SUMIFS(猫统计!AJ:AJ,猫统计!AH:AH,">="&EOMONTH(A17,-1)+1,猫统计!AH:AH,"<="&EOMONTH(A17,0))+SUMIFS(猫统计!AP:AP,猫统计!AN:AN,">="&EOMONTH(A17,-1)+1,猫统计!AN:AN,"<="&EOMONTH(A17,0))+SUMIFS(猫统计!AV:AV,猫统计!AT:AT,">="&EOMONTH(A17,-1)+1,猫统计!AT:AT,"<="&EOMONTH(A17,0))+SUMIFS(猫统计!BB:BB,猫统计!AZ:AZ,">="&EOMONTH(A17,-1)+1,猫统计!AZ:AZ,"<="&EOMONTH(A17,0))+SUMIFS(猫统计!BH:BH,猫统计!BF:BF,">="&EOMONTH(A17,-1)+1,猫统计!BF:BF,"<="&EOMONTH(A17,0))+SUMIFS(猫统计!BN:BN,猫统计!BL:BL,">="&EOMONTH(A17,-1)+1,猫统计!BL:BL,"<="&EOMONTH(A17,0)) -> 4 | E17: =SUMIFS(猫统计!M:M,猫统计!J:J,">="&EOMONTH(A17,-1)+1,猫统计!J:J,"<="&EOMONTH(A17,0))+SUMIFS(猫统计!S:S,猫统计!P:P,">="&EOMONTH(A17,-1)+1,猫统计!P:P,"<="&EOMONTH(A17,0))+SUMIFS(猫统计!Y:Y,猫统计!V:V,">="&EOMONTH(A17,-1)+1,猫统计!V:V,"<="&EOMONTH(A17,0))+SUMIFS(猫统计!AE:AE,猫统计!AB:AB,">="&EOMONTH(A17,-1)+1,猫统计!AB:AB,"<="&EOMONTH(A17,0))+SUMIFS(猫统计!AK:AK,猫统计!AH:AH,">="&EOMONTH(A17,-1)+1,猫统计!AH:AH,"<="&EOMONTH(A17,0))+SUMIFS(猫统计!AQ:AQ,猫统计!AN:AN,">="&EOMONTH(A17,-1)+1,猫统计!AN:AN,"<="&EOMONTH(A17,0))+SUMIFS(猫统计!AW:AW,猫统计!AT:AT,">="&EOMONTH(A17,-1)+1,猫统计!AT:AT,"<="&EOMONTH(A17,0))+SUMIFS(猫统计!BC:BC,猫统计!AZ:AZ,">="&EOMONTH(A17,-1)+1,猫统计!AZ:AZ,"<="&EOMONTH(A17,0))+SUMIFS(猫统计!BI:BI,猫统计!BF:BF,">="&EOMONTH(A17,-1)+1,猫统计!BF:BF,"<="&EOMONTH(A17,0))+SUMIFS(猫统计!BO:BO,猫统计!BL:BL,">="&EOMONTH(A17,-1)+1,猫统计!BL:BL,"<="&EOMONTH(A17,0)) -> 13
A18: 44501 | B18: =COUNTIFS(猫统计!J:J,">="&EOMONTH(A18,-1)+1,猫统计!J:J,"<="&EOMONTH(A18,0))+COUNTIFS(猫统计!P:P,">="&EOMONTH(A18,-1)+1,猫统计!P:P,"<="&EOMONTH(A18,0))+COUNTIFS(猫统计!V:V,">="&EOMONTH(A18,-1)+1,猫统计!V:V,"<="&EOMONTH(A18,0))+COUNTIFS(猫统计!AB:AB,">="&EOMONTH(A18,-1)+1,猫统计!AB:AB,"<="&EOMONTH(A18,0))+COUNTIFS(猫统计!AH:AH,">="&EOMONTH(A18,-1)+1,猫统计!AH:AH,"<="&EOMONTH(A18,0))+COUNTIFS(猫统计!AN:AN,">="&EOMONTH(A18,-1)+1,猫统计!AN:AN,"<="&EOMONTH(A18,0))+COUNTIFS(猫统计!AT:AT,">="&EOMONTH(A18,-1)+1,猫统计!AT:AT,"<="&EOMONTH(A18,0))+COUNTIFS(猫统计!AZ:AZ,">="&EOMONTH(A18,-1)+1,猫统计!AZ:AZ,"<="&EOMONTH(A18,0))+COUNTIFS(猫统计!BF:BF,">="&EOMONTH(A18,-1)+1,猫统计!BF:BF,"<="&EOMONTH(A18,0))+COUNTIFS(猫统计!BL:BL,">="&EOMONTH(A18,-1)+1,猫统计!BL:BL,"<="&EOMONTH(A18,0)) -> 1 | C18: =D18+E18 -> 3 | D18: =SUMIFS(猫统计!L:L,猫统计!J:J,">="&EOMONTH(A18,-1)+1,猫统计!J:J,"<="&EOMONTH(A18,0))+SUMIFS(猫统计!R:R,猫统计!P:P,">="&EOMONTH(A18,-1)+1,猫统计!P:P,"<="&EOMONTH(A18,0))+SUMIFS(猫统计!X:X,猫统计!V:V,">="&EOMONTH(A18,-1)+1,猫统计!V:V,"<="&EOMONTH(A18,0))+SUMIFS(猫统计!AD:AD,猫统计!AB:AB,">="&EOMONTH(A18,-1)+1,猫统计!AB:AB,"<="&EOMONTH(A18,0))+SUMIFS(猫统计!AJ:AJ,猫统计!AH:AH,">="&EOMONTH(A18,-1)+1,猫统计!AH:AH,"<="&EOMONTH(A18,0))+SUMIFS(猫统计!AP:AP,猫统计!AN:AN,">="&EOMONTH(A18,-1)+1,猫统计!AN:AN,"<="&EOMONTH(A18,0))+SUMIFS(猫统计!AV:AV,猫统计!AT:AT,">="&EOMONTH(A18,-1)+1,猫统计!AT:AT,"<="&EOMONTH(A18,0))+SUMIFS(猫统计!BB:BB,猫统计!AZ:AZ,">="&EOMONTH(A18,-1)+1,猫统计!AZ:AZ,"<="&EOMONTH(A18,0))+SUMIFS(猫统计!BH:BH,猫统计!BF:BF,">="&EOMONTH(A18,-1)+1,猫统计!BF:BF,"<="&EOMONTH(A18,0))+SUMIFS(猫统计!BN:BN,猫统计!BL:BL,">="&EOMONTH(A18,-1)+1,猫统计!BL:BL,"<="&EOMONTH(A18,0)) -> 0 | E18: =SUMIFS(猫统计!M:M,猫统计!J:J,">="&EOMONTH(A18,-1)+1,猫统计!J:J,"<="&EOMONTH(A18,0))+SUMIFS(猫统计!S:S,猫统计!P:P,">="&EOMONTH(A18,-1)+1,猫统计!P:P,"<="&EOMONTH(A18,0))+SUMIFS(猫统计!Y:Y,猫统计!V:V,">="&EOMONTH(A18,-1)+1,猫统计!V:V,"<="&EOMONTH(A18,0))+SUMIFS(猫统计!AE:AE,猫统计!AB:AB,">="&EOMONTH(A18,-1)+1,猫统计!AB:AB,"<="&EOMONTH(A18,0))+SUMIFS(猫统计!AK:AK,猫统计!AH:AH,">="&EOMONTH(A18,-1)+1,猫统计!AH:AH,"<="&EOMONTH(A18,0))+SUMIFS(猫统计!AQ:AQ,猫统计!AN:AN,">="&EOMONTH(A18,-1)+1,猫统计!AN:AN,"<="&EOMONTH(A18,0))+SUMIFS(猫统计!AW:AW,猫统计!AT:AT,">="&EOMONTH(A18,-1)+1,猫统计!AT:AT,"<="&EOMONTH(A18,0))+SUMIFS(猫统计!BC:BC,猫统计!AZ:AZ,">="&EOMONTH(A18,-1)+1,猫统计!AZ:AZ,"<="&EOMONTH(A18,0))+SUMIFS(猫统计!BI:BI,猫统计!BF:BF,">="&EOMONTH(A18,-1)+1,猫统计!BF:BF,"<="&EOMONTH(A18,0))+SUMIFS(猫统计!BO:BO,猫统计!BL:BL,">="&EOMONTH(A18,-1)+1,猫统计!BL:BL,"<="&EOMONTH(A18,0)) -> 3
A19: 44531 | B19: =COUNTIFS(猫统计!J:J,">="&EOMONTH(A19,-1)+1,猫统计!J:J,"<="&EOMONTH(A19,0))+COUNTIFS(猫统计!P:P,">="&EOMONTH(A19,-1)+1,猫统计!P:P,"<="&EOMONTH(A19,0))+COUNTIFS(猫统计!V:V,">="&EOMONTH(A19,-1)+1,猫统计!V:V,"<="&EOMONTH(A19,0))+COUNTIFS(猫统计!AB:AB,">="&EOMONTH(A19,-1)+1,猫统计!AB:AB,"<="&EOMONTH(A19,0))+COUNTIFS(猫统计!AH:AH,">="&EOMONTH(A19,-1)+1,猫统计!AH:AH,"<="&EOMONTH(A19,0))+COUNTIFS(猫统计!AN:AN,">="&EOMONTH(A19,-1)+1,猫统计!AN:AN,"<="&EOMONTH(A19,0))+COUNTIFS(猫统计!AT:AT,">="&EOMONTH(A19,-1)+1,猫统计!AT:AT,"<="&EOMONTH(A19,0))+COUNTIFS(猫统计!AZ:AZ,">="&EOMONTH(A19,-1)+1,猫统计!AZ:AZ,"<="&EOMONTH(A19,0))+COUNTIFS(猫统计!BF:BF,">="&EOMONTH(A19,-1)+1,猫统计!BF:BF,"<="&EOMONTH(A19,0))+COUNTIFS(猫统计!BL:BL,">="&EOMONTH(A19,-1)+1,猫统计!BL:BL,"<="&EOMONTH(A19,0)) -> 1 | C19: =D19+E19 -> 5 | D19: =SUMIFS(猫统计!L:L,猫统计!J:J,">="&EOMONTH(A19,-1)+1,猫统计!J:J,"<="&EOMONTH(A19,0))+SUMIFS(猫统计!R:R,猫统计!P:P,">="&EOMONTH(A19,-1)+1,猫统计!P:P,"<="&EOMONTH(A19,0))+SUMIFS(猫统计!X:X,猫统计!V:V,">="&EOMONTH(A19,-1)+1,猫统计!V:V,"<="&EOMONTH(A19,0))+SUMIFS(猫统计!AD:AD,猫统计!AB:AB,">="&EOMONTH(A19,-1)+1,猫统计!AB:AB,"<="&EOMONTH(A19,0))+SUMIFS(猫统计!AJ:AJ,猫统计!AH:AH,">="&EOMONTH(A19,-1)+1,猫统计!AH:AH,"<="&EOMONTH(A19,0))+SUMIFS(猫统计!AP:AP,猫统计!AN:AN,">="&EOMONTH(A19,-1)+1,猫统计!AN:AN,"<="&EOMONTH(A19,0))+SUMIFS(猫统计!AV:AV,猫统计!AT:AT,">="&EOMONTH(A19,-1)+1,猫统计!AT:AT,"<="&EOMONTH(A19,0))+SUMIFS(猫统计!BB:BB,猫统计!AZ:AZ,">="&EOMONTH(A19,-1)+1,猫统计!AZ:AZ,"<="&EOMONTH(A19,0))+SUMIFS(猫统计!BH:BH,猫统计!BF:BF,">="&EOMONTH(A19,-1)+1,猫统计!BF:BF,"<="&EOMONTH(A19,0))+SUMIFS(猫统计!BN:BN,猫统计!BL:BL,">="&EOMONTH(A19,-1)+1,猫统计!BL:BL,"<="&EOMONTH(A19,0)) -> 0 | E19: =SUMIFS(猫统计!M:M,猫统计!J:J,">="&EOMONTH(A19,-1)+1,猫统计!J:J,"<="&EOMONTH(A19,0))+SUMIFS(猫统计!S:S,猫统计!P:P,">="&EOMONTH(A19,-1)+1,猫统计!P:P,"<="&EOMONTH(A19,0))+SUMIFS(猫统计!Y:Y,猫统计!V:V,">="&EOMONTH(A19,-1)+1,猫统计!V:V,"<="&EOMONTH(A19,0))+SUMIFS(猫统计!AE:AE,猫统计!AB:AB,">="&EOMONTH(A19,-1)+1,猫统计!AB:AB,"<="&EOMONTH(A19,0))+SUMIFS(猫统计!AK:AK,猫统计!AH:AH,">="&EOMONTH(A19,-1)+1,猫统计!AH:AH,"<="&EOMONTH(A19,0))+SUMIFS(猫统计!AQ:AQ,猫统计!AN:AN,">="&EOMONTH(A19,-1)+1,猫统计!AN:AN,"<="&EOMONTH(A19,0))+SUMIFS(猫统计!AW:AW,猫统计!AT:AT,">="&EOMONTH(A19,-1)+1,猫统计!AT:AT,"<="&EOMONTH(A19,0))+SUMIFS(猫统计!BC:BC,猫统计!AZ:AZ,">="&EOMONTH(A19,-1)+1,猫统计!AZ:AZ,"<="&EOMONTH(A19,0))+SUMIFS(猫统计!BI:BI,猫统计!BF:BF,">="&EOMONTH(A19,-1)+1,猫统计!BF:BF,"<="&EOMONTH(A19,0))+SUMIFS(猫统计!BO:BO,猫统计!BL:BL,">="&EOMONTH(A19,-1)+1,猫统计!BL:BL,"<="&EOMONTH(A19,0)) -> 5 | F19: =(E17+E18+E19)/(C17+C18+C19) -> 0.84 | G19: =(E17+E18+E19)/(B17+B18+B19) -> 4.2
A20: 44562 | B20: =COUNTIFS(猫统计!J:J,">="&EOMONTH(A20,-1)+1,猫统计!J:J,"<="&EOMONTH(A20,0))+COUNTIFS(猫统计!P:P,">="&EOMONTH(A20,-1)+1,猫统计!P:P,"<="&EOMONTH(A20,0))+COUNTIFS(猫统计!V:V,">="&EOMONTH(A20,-1)+1,猫统计!V:V,"<="&EOMONTH(A20,0))+COUNTIFS(猫统计!AB:AB,">="&EOMONTH(A20,-1)+1,猫统计!AB:AB,"<="&EOMONTH(A20,0))+COUNTIFS(猫统计!AH:AH,">="&EOMONTH(A20,-1)+1,猫统计!AH:AH,"<="&EOMONTH(A20,0))+COUNTIFS(猫统计!AN:AN,">="&EOMONTH(A20,-1)+1,猫统计!AN:AN,"<="&EOMONTH(A20,0))+COUNTIFS(猫统计!AT:AT,">="&EOMONTH(A20,-1)+1,猫统计!AT:AT,"<="&EOMONTH(A20,0))+COUNTIFS(猫统计!AZ:AZ,">="&EOMONTH(A20,-1)+1,猫统计!AZ:AZ,"<="&EOMONTH(A20,0))+COUNTIFS(猫统计!BF:BF,">="&EOMONTH(A20,-1)+1,猫统计!BF:BF,"<="&EOMONTH(A20,0))+COUNTIFS(猫统计!BL:BL,">="&EOMONTH(A20,-1)+1,猫统计!BL:BL,"<="&EOMONTH(A20,0)) -> 2 | C20: =D20+E20 -> 10 | D20: =SUMIFS(猫统计!L:L,猫统计!J:J,">="&EOMONTH(A20,-1)+1,猫统计!J:J,"<="&EOMONTH(A20,0))+SUMIFS(猫统计!R:R,猫统计!P:P,">="&EOMONTH(A20,-1)+1,猫统计!P:P,"<="&EOMONTH(A20,0))+SUMIFS(猫统计!X:X,猫统计!V:V,">="&EOMONTH(A20,-1)+1,猫统计!V:V,"<="&EOMONTH(A20,0))+SUMIFS(猫统计!AD:AD,猫统计!AB:AB,">="&EOMONTH(A20,-1)+1,猫统计!AB:AB,"<="&EOMONTH(A20,0))+SUMIFS(猫统计!AJ:AJ,猫统计!AH:AH,">="&EOMONTH(A20,-1)+1,猫统计!AH:AH,"<="&EOMONTH(A20,0))+SUMIFS(猫统计!AP:AP,猫统计!AN:AN,">="&EOMONTH(A20,-1)+1,猫统计!AN:AN,"<="&EOMONTH(A20,0))+SUMIFS(猫统计!AV:AV,猫统计!AT:AT,">="&EOMONTH(A20,-1)+1,猫统计!AT:AT,"<="&EOMONTH(A20,0))+SUMIFS(猫统计!BB:BB,猫统计!AZ:AZ,">="&EOMONTH(A20,-1)+1,猫统计!AZ:AZ,"<="&EOMONTH(A20,0))+SUMIFS(猫统计!BH:BH,猫统计!BF:BF,">="&EOMONTH(A20,-1)+1,猫统计!BF:BF,"<="&EOMONTH(A20,0))+SUMIFS(猫统计!BN:BN,猫统计!BL:BL,">="&EOMONTH(A20,-1)+1,猫统计!BL:BL,"<="&EOMONTH(A20,0)) -> 4 | E20: =SUMIFS(猫统计!M:M,猫统计!J:J,">="&EOMONTH(A20,-1)+1,猫统计!J:J,"<="&EOMONTH(A20,0))+SUMIFS(猫统计!S:S,猫统计!P:P,">="&EOMONTH(A20,-1)+1,猫统计!P:P,"<="&EOMONTH(A20,0))+SUMIFS(猫统计!Y:Y,猫统计!V:V,">="&EOMONTH(A20,-1)+1,猫统计!V:V,"<="&EOMONTH(A20,0))+SUMIFS(猫统计!AE:AE,猫统计!AB:AB,">="&EOMONTH(A20,-1)+1,猫统计!AB:AB,"<="&EOMONTH(A20,0))+SUMIFS(猫统计!AK:AK,猫统计!AH:AH,">="&EOMONTH(A20,-1)+1,猫统计!AH:AH,"<="&EOMONTH(A20,0))+SUMIFS(猫统计!AQ:AQ,猫统计!AN:AN,">="&EOMONTH(A20,-1)+1,猫统计!AN:AN,"<="&EOMONTH(A20,0))+SUMIFS(猫统计!AW:AW,猫统计!AT:AT,">="&EOMONTH(A20,-1)+1,猫统计!AT:AT,"<="&EOMONTH(A20,0))+SUMIFS(猫统计!BC:BC,猫统计!AZ:AZ,">="&EOMONTH(A20,-1)+1,猫统计!AZ:AZ,"<="&EOMONTH(A20,0))+SUMIFS(猫统计!BI:BI,猫统计!BF:BF,">="&EOMONTH(A20,-1)+1,猫统计!BF:BF,"<="&EOMONTH(A20,0))+SUMIFS(猫统计!BO:BO,猫统计!BL:BL,">="&EOMONTH(A20,-1)+1,猫统计!BL:BL,"<="&EOMONTH(A20,0)) -> 6
A21: 44593 | B21: =COUNTIFS(猫统计!J:J,">="&EOMONTH(A21,-1)+1,猫统计!J:J,"<="&EOMONTH(A21,0))+COUNTIFS(猫统计!P:P,">="&EOMONTH(A21,-1)+1,猫统计!P:P,"<="&EOMONTH(A21,0))+COUNTIFS(猫统计!V:V,">="&EOMONTH(A21,-1)+1,猫统计!V:V,"<="&EOMONTH(A21,0))+COUNTIFS(猫统计!AB:AB,">="&EOMONTH(A21,-1)+1,猫统计!AB:AB,"<="&EOMONTH(A21,0))+COUNTIFS(猫统计!AH:AH,">="&EOMONTH(A21,-1)+1,猫统计!AH:AH,"<="&EOMONTH(A21,0))+COUNTIFS(猫统计!AN:AN,">="&EOMONTH(A21,-1)+1,猫统计!AN:AN,"<="&EOMONTH(A21,0))+COUNTIFS(猫统计!AT:AT,">="&EOMONTH(A21,-1)+1,猫统计!AT:AT,"<="&EOMONTH(A21,0))+COUNTIFS(猫统计!AZ:AZ,">="&EOMONTH(A21,-1)+1,猫统计!AZ:AZ,"<="&EOMONTH(A21,0))+COUNTIFS(猫统计!BF:BF,">="&EOMONTH(A21,-1)+1,猫统计!BF:BF,"<="&EOMONTH(A21,0))+COUNTIFS(猫统计!BL:BL,">="&EOMONTH(A21,-1)+1,猫统计!BL:BL,"<="&EOMONTH(A21,0)) -> 1 | C21: =D21+E21 -> 4 | D21: =SUMIFS(猫统计!L:L,猫统计!J:J,">="&EOMONTH(A21,-1)+1,猫统计!J:J,"<="&EOMONTH(A21,0))+SUMIFS(猫统计!R:R,猫统计!P:P,">="&EOMONTH(A21,-1)+1,猫统计!P:P,"<="&EOMONTH(A21,0))+SUMIFS(猫统计!X:X,猫统计!V:V,">="&EOMONTH(A21,-1)+1,猫统计!V:V,"<="&EOMONTH(A21,0))+SUMIFS(猫统计!AD:AD,猫统计!AB:AB,">="&EOMONTH(A21,-1)+1,猫统计!AB:AB,"<="&EOMONTH(A21,0))+SUMIFS(猫统计!AJ:AJ,猫统计!AH:AH,">="&EOMONTH(A21,-1)+1,猫统计!AH:AH,"<="&EOMONTH(A21,0))+SUMIFS(猫统计!AP:AP,猫统计!AN:AN,">="&EOMONTH(A21,-1)+1,猫统计!AN:AN,"<="&EOMONTH(A21,0))+SUMIFS(猫统计!AV:AV,猫统计!AT:AT,">="&EOMONTH(A21,-1)+1,猫统计!AT:AT,"<="&EOMONTH(A21,0))+SUMIFS(猫统计!BB:BB,猫统计!AZ:AZ,">="&EOMONTH(A21,-1)+1,猫统计!AZ:AZ,"<="&EOMONTH(A21,0))+SUMIFS(猫统计!BH:BH,猫统计!BF:BF,">="&EOMONTH(A21,-1)+1,猫统计!BF:BF,"<="&EOMONTH(A21,0))+SUMIFS(猫统计!BN:BN,猫统计!BL:BL,">="&EOMONTH(A21,-1)+1,猫统计!BL:BL,"<="&EOMONTH(A21,0)) -> 0 | E21: =SUMIFS(猫统计!M:M,猫统计!J:J,">="&EOMONTH(A21,-1)+1,猫统计!J:J,"<="&EOMONTH(A21,0))+SUMIFS(猫统计!S:S,猫统计!P:P,">="&EOMONTH(A21,-1)+1,猫统计!P:P,"<="&EOMONTH(A21,0))+SUMIFS(猫统计!Y:Y,猫统计!V:V,">="&EOMONTH(A21,-1)+1,猫统计!V:V,"<="&EOMONTH(A21,0))+SUMIFS(猫统计!AE:AE,猫统计!AB:AB,">="&EOMONTH(A21,-1)+1,猫统计!AB:AB,"<="&EOMONTH(A21,0))+SUMIFS(猫统计!AK:AK,猫统计!AH:AH,">="&EOMONTH(A21,-1)+1,猫统计!AH:AH,"<="&EOMONTH(A21,0))+SUMIFS(猫统计!AQ:AQ,猫统计!AN:AN,">="&EOMONTH(A21,-1)+1,猫统计!AN:AN,"<="&EOMONTH(A21,0))+SUMIFS(猫统计!AW:AW,猫统计!AT:AT,">="&EOMONTH(A21,-1)+1,猫统计!AT:AT,"<="&EOMONTH(A21,0))+SUMIFS(猫统计!BC:BC,猫统计!AZ:AZ,">="&EOMONTH(A21,-1)+1,猫统计!AZ:AZ,"<="&EOMONTH(A21,0))+SUMIFS(猫统计!BI:BI,猫统计!BF:BF,">="&EOMONTH(A21,-1)+1,猫统计!BF:BF,"<="&EOMONTH(A21,0))+SUMIFS(猫统计!BO:BO,猫统计!BL:BL,">="&EOMONTH(A21,-1)+1,猫统计!BL:BL,"<="&EOMONTH(A21,0)) -> 4
A22: 44621 | B22: =COUNTIFS(猫统计!J:J,">="&EOMONTH(A22,-1)+1,猫统计!J:J,"<="&EOMONTH(A22,0))+COUNTIFS(猫统计!P:P,">="&EOMONTH(A22,-1)+1,猫统计!P:P,"<="&EOMONTH(A22,0))+COUNTIFS(猫统计!V:V,">="&EOMONTH(A22,-1)+1,猫统计!V:V,"<="&EOMONTH(A22,0))+COUNTIFS(猫统计!AB:AB,">="&EOMONTH(A22,-1)+1,猫统计!AB:AB,"<="&EOMONTH(A22,0))+COUNTIFS(猫统计!AH:AH,">="&EOMONTH(A22,-1)+1,猫统计!AH:AH,"<="&EOMONTH(A22,0))+COUNTIFS(猫统计!AN:AN,">="&EOMONTH(A22,-1)+1,猫统计!AN:AN,"<="&EOMONTH(A22,0))+COUNTIFS(猫统计!AT:AT,">="&EOMONTH(A22,-1)+1,猫统计!AT:AT,"<="&EOMONTH(A22,0))+COUNTIFS(猫统计!AZ:AZ,">="&EOMONTH(A22,-1)+1,猫统计!AZ:AZ,"<="&EOMONTH(A22,0))+COUNTIFS(猫统计!BF:BF,">="&EOMONTH(A22,-1)+1,猫统计!BF:BF,"<="&EOMONTH(A22,0))+COUNTIFS(猫统计!BL:BL,">="&EOMONTH(A22,-1)+1,猫统计!BL:BL,"<="&EOMONTH(A22,0)) -> 2 | C22: =D22+E22 -> 11 | D22: =SUMIFS(猫统计!L:L,猫统计!J:J,">="&EOMONTH(A22,-1)+1,猫统计!J:J,"<="&EOMONTH(A22,0))+SUMIFS(猫统计!R:R,猫统计!P:P,">="&EOMONTH(A22,-1)+1,猫统计!P:P,"<="&EOMONTH(A22,0))+SUMIFS(猫统计!X:X,猫统计!V:V,">="&EOMONTH(A22,-1)+1,猫统计!V:V,"<="&EOMONTH(A22,0))+SUMIFS(猫统计!AD:AD,猫统计!AB:AB,">="&EOMONTH(A22,-1)+1,猫统计!AB:AB,"<="&EOMONTH(A22,0))+SUMIFS(猫统计!AJ:AJ,猫统计!AH:AH,">="&EOMONTH(A22,-1)+1,猫统计!AH:AH,"<="&EOMONTH(A22,0))+SUMIFS(猫统计!AP:AP,猫统计!AN:AN,">="&EOMONTH(A22,-1)+1,猫统计!AN:AN,"<="&EOMONTH(A22,0))+SUMIFS(猫统计!AV:AV,猫统计!AT:AT,">="&EOMONTH(A22,-1)+1,猫统计!AT:AT,"<="&EOMONTH(A22,0))+SUMIFS(猫统计!BB:BB,猫统计!AZ:AZ,">="&EOMONTH(A22,-1)+1,猫统计!AZ:AZ,"<="&EOMONTH(A22,0))+SUMIFS(猫统计!BH:BH,猫统计!BF:BF,">="&EOMONTH(A22,-1)+1,猫统计!BF:BF,"<="&EOMONTH(A22,0))+SUMIFS(猫统计!BN:BN,猫统计!BL:BL,">="&EOMONTH(A22,-1)+1,猫统计!BL:BL,"<="&EOMONTH(A22,0)) -> 1 | E22: =SUMIFS(猫统计!M:M,猫统计!J:J,">="&EOMONTH(A22,-1)+1,猫统计!J:J,"<="&EOMONTH(A22,0))+SUMIFS(猫统计!S:S,猫统计!P:P,">="&EOMONTH(A22,-1)+1,猫统计!P:P,"<="&EOMONTH(A22,0))+SUMIFS(猫统计!Y:Y,猫统计!V:V,">="&EOMONTH(A22,-1)+1,猫统计!V:V,"<="&EOMONTH(A22,0))+SUMIFS(猫统计!AE:AE,猫统计!AB:AB,">="&EOMONTH(A22,-1)+1,猫统计!AB:AB,"<="&EOMONTH(A22,0))+SUMIFS(猫统计!AK:AK,猫统计!AH:AH,">="&EOMONTH(A22,-1)+1,猫统计!AH:AH,"<="&EOMONTH(A22,0))+SUMIFS(猫统计!AQ:AQ,猫统计!AN:AN,">="&EOMONTH(A22,-1)+1,猫统计!AN:AN,"<="&EOMONTH(A22,0))+SUMIFS(猫统计!AW:AW,猫统计!AT:AT,">="&EOMONTH(A22,-1)+1,猫统计!AT:AT,"<="&EOMONTH(A22,0))+SUMIFS(猫统计!BC:BC,猫统计!AZ:AZ,">="&EOMONTH(A22,-1)+1,猫统计!AZ:AZ,"<="&EOMONTH(A22,0))+SUMIFS(猫统计!BI:BI,猫统计!BF:BF,">="&EOMONTH(A22,-1)+1,猫统计!BF:BF,"<="&EOMONTH(A22,0))+SUMIFS(猫统计!BO:BO,猫统计!BL:BL,">="&EOMONTH(A22,-1)+1,猫统计!BL:BL,"<="&EOMONTH(A22,0)) -> 10 | F22: =(E20+E21+E22)/(C20+C21+C22) -> 0.8 | G22: =(E20+E21+E22)/(B20+B21+B22) -> 4
